Workbook

Sheet 1__POR_RECEITA_DETALHADA
E2: conta | F2: 8460335.7
A3: EMOLUMENTOS E CUSTAS JUDICIAIS 2023 | AI3: Processo 8525633-69.2023.8.06.0000 – AUDITORIA
B4: CUSTAS PROCESSUAIS | E4: CUSTAS RECUPERADAS | H4: TOTAL CUSTAS PROCESSUAIS | M4: CUSTAS DA DÍVIDA ATIVA | T4: TAXA OFICIAIS DE JUSTIÇA | Y4: % DESTINADO AO FUNSEG
A5: MÊS | B5: DAES | C5: REJEITADOS | D5: TOTAL | E5: DAES | F5: REJEITADOS | H5: DAES | I5: REJEITADOS | J5: SUB-TOTAL | K5: AJUSTE | L5: TOTAL | M5: DAES | N5: REJEITADOS | O5: TOTAL | S5: MÊS | T5: DAES | U5: REJEITADOS | V5: TOTAL | X5: MÊS | Y5: CUSTAS | Z5: RECUPERADA | AA5: DÍVIDA ATIVA | AB5: TOTAL | AI5: custas | AJ5: recup | AK5: dívida | AL5: total | AM5: 3% total | AS5: TRANSF | AV5: OBSERVAÇÕES:
A6: Janeiro | B6: =11436684.82 -> 11436685 | C6: 38915.62 | D6: =(B6+C6)*0.97+1618.87 -> 11132951 | E6: 2439.68 | F6: 0 | G6: =(E6+F6)*0.97 -> 2366.4896 | H6: =(B6+E6)*0.97 -> 11095951 | I6: =(C6+F6)*0.97 -> 37748.151 | J6: =H6+I6 -> 11133699 | K6: 1032.35 | L6: =J6+K6 -> 11134731 | M6: 451556.22 | O6: =(M6+N6)*0.97+0.58 -> 438010.11 | Q6: 731388.61 | S6: Janeiro | T6: 393761.98 | U6: 906.6 | V6: =T6+U6 -> 394668.58 | X6: Janeiro | Y6: =D6*0.03 -> 333988.54 | Z6: =G6*0.03 -> 70.994688 | AA6: =O6*0.03 -> 13140.303 | AB6: =Y6+Z6+AA6 -> 347199.84 | AC6: CPA 8503509-92.2023.8.06.0000 | AF6: 0 | AH6: Janeiro | AI6: 10638858 | AJ6: =E6 -> 2439.68 | AK6: =M6 -> 451556.22 | AL6: =SUM(AI6:AK6) -> 11092853 | AM6: =AL6*0.03 -> 332785.6 | AO6: Janeiro | AS6: 323245.83
A7: Fevereiro | B7: 14805140 | C7: 85445.57 | D7: =(B7+C7)*0.97+1032.35 -> 14444900 | E7: 18924.76 | G7: =(E7+F7)*0.97 -> 18357.017 | I7: =(C7+F7)*0.97 -> 82882.203 | J7: =H7+I7 -> 82882.203 | L7: =J7+K7 -> 82882.203 | M7: 366330.63 | N7: 8385.34 | O7: =(M7+N7)*0.97+1.54 -> 363476.03 | P7: =O7-363476.03 -> 0.00089999998 | Q7: 908145.8 | S7: Fevereiro | V7: =T7+U7 -> 0 | X7: Fevereiro | Y7: =D7*0.03 -> 433347.01 | Z7: =G7*0.03 -> 550.71052 | AA7: =O7*0.03 -> 10904.281 | AB7: =Y7+Z7+AA7 -> 444802.01 | AC7: CPA nº 8506647-67.2023.8.06.0000 | AF7: 661988.96 | AH7: Fevereiro | AI7: 11205142 | AJ7: =E7 -> 18924.76 | AK7: =M7 -> 366330.63 | AL7: =SUM(AI7:AK7) -> 11590397 | AM7: =AL7*0.03 -> 347711.91 | AO7: Fevereiro | AP7: =AM7+AM6 -> 680497.51 | AS7: 340449.78 | AV7: No relatório da AUDIN foi considerado no mês de fev/2023 o valor relativo a dez/22(R$ 313.394,11)
A8: Março | B8: 8016787.9 | D8: =(B8+C8)*0.97 -> 7776284.2 | E8: 7674.37 | G8: =(E8+F8)*0.97 -> 7444.1389 | H8: =(B8+E8)*0.97 -> 7783728.4 | I8: =(C8+F8)*0.97 -> 0 | J8: =H8+I8 -> 7783728.4 | L8: =J8+K8 -> 7783728.4 | M8: 60999.53 | O8: =(M8+N8)*0.97 -> 59169.544 | S8: Março | V8: =T8+U8 -> 0 | X8: Março | Y8: =D8*0.03 -> 233288.53 | Z8: =G8*0.03 -> 223.32417 | AA8: =O8*0.03 -> 1775.0863 | AB8: =Y8+Z8+AA8 -> 235286.94 | AC8: CPA nº 8508905-50.2023.8.06.0000 | AF8: 0 | AH8: Março | AI8: 13906586 | AJ8: =E8 -> 7674.37 | AK8: =M8 -> 60999.53 | AL8: =SUM(AI8:AK8) -> 13975260 | AM8: =AL8*0.03 -> 419257.79 | AO8: Março | AS8: 423200.37 | AV8: Valor de fev/2023 e mar entraram em abril
A9: Abril | D9: =(B9+C9)*0.97 -> 0 | G9: =(E9+F9)*0.97 -> 0 | H9: =((B9+E9)*0.97) -> 0 | I9: =(C9+F9)*0.97 -> 0 | J9: =H9+I9 -> 0 | L9: =J9+K9 -> 0 | O9: =(M9+N9)*0.97 -> 0 | Q9: =B6+E6+M6+Q6+Q7+T6 -> 13923977 | S9: Abril | V9: =T9+U9 -> 0 | X9: Abril | Y9: =D9*0.03 -> 0 | Z9: =G9*0.03 -> 0 | AA9: =O9*0.03 -> 0 | AB9: =Y9+Z9+AA9 -> 0 | AC9: CPA nº 8511380-76.2023.8.06.0000 | AF9: 763650.15 | AH9: Abril | AI9: 10996722 | AJ9: =E9 -> 0 | AK9: =M9 -> 0 | AL9: =SUM(AI9:AK9) -> 10996722 | AM9: =AL9*0.03 -> 329901.67 | AO9: Abril | AP9: =AM8+AM9 -> 749159.46 | AS9: 335005.81
A10: Maio | D10: =(B10+C10)*0.97 -> 0 | G10: =(E10+F10)*0.97 -> 0 | H10: =(B10+E10)*0.97 -> 0 | I10: =(C10+F10)*0.97 -> 0 | J10: =H10+I10 -> 0 | L10: =J10+K10 -> 0 | O10: =(M10+N10)*0.97 -> 0 | P10: =O10+G10+C10+B10 -> 0 | Q10: =O10-P10 -> 0 | S10: Maio | V10: =T10+U10 -> 0 | X10: Maio | Y10: =D10*0.03 -> 0 | Z10: =G10*0.03 -> 0 | AA10: =O10*0.03 -> 0 | AB10: =Y10+Z10+AA10 -> 0 | AC10: CPA nº 8518333-56.2023.8.06.0000 | AF10: 444385.23 | AH10: Maio | AI10: 14673254 | AJ10: =E10 -> 0 | AK10: =M10 -> 0 | AL10: =SUM(AI10:AK10) -> 14673254 | AM10: =AL10*0.03 -> 440197.62 | AO10: Maio | AP10: =AM10 -> 440197.62 | AS10: 445395.38
A11: Junho | D11: =(B11+C11)*0.97 -> 0 | G11: =(E11+F11)*0.97 -> 0 | H11: =(B11+E11)*0.97 -> 0 | I11: =(C11+F11)*0.97 -> 0 | J11: =H11+I11 -> 0 | L11: =J11+K11 -> 0 | O11: =(M11+N11)*0.97 -> 0 | P11: =P10*0.03 -> 0 | S11: Junho | V11: =T11+U11 -> 0 | X11: Junho | Y11: =D11*0.03 -> 0 | Z11: =G11*0.03 -> 0 | AA11: =O11*0.03 -> 0 | AB11: =Y11+Z11+AA11 -> 0 | AC11: CPA nº 8516027-17.2023.8.06.0000 | AF11: 0 | AH11: Junho | AI11: 15203719 | AJ11: =E11 -> 0 | AK11: =M11 -> 0 | AL11: =SUM(AI11:AK11) -> 15203719 | AM11: =AL11*0.03 -> 456111.58 | AO11: Junho | AS11: 461567.61
A12: Julho | D12: =(B12+C12)*0.97 -> 0 | G12: =(E12+F12)*0.97 -> 0 | H12: =(B12+E12)*0.97 -> 0 | I12: =(C12+F12)*0.97 -> 0 | J12: =H12+I12 -> 0 | L12: =J12+K12 -> 0 | O12: =(M12+N12)*0.97 -> 0 | P12: =O12+L12 -> 0 | Q12: =(12085/10638)-1 -> 0.13602181 | S12: Julho | V12: =T12+U12 -> 0 | X12: Julho | Y12: =D12*0.03 -> 0 | Z12: =G12*0.03 -> 0 | AA12: =O12*0.03 -> 0 | AB12: =Y12+Z12+AA12 -> 0 | AC12: CPA nº 8518333-56.2023.8.06.0000 | AF12: 921133.85 | AH12: Julho | AI12: 15105471 | AJ12: =E12 -> 0 | AK12: =M12 -> 0 | AL12: =SUM(AI12:AK12) -> 15105471 | AM12: =AL12*0.03 -> 453164.13 | AO12: Julho | AP12: =AM11+AM12 -> 909275.71 | AS12: 462291.67
A13: Agosto | D13: =(B13+C13)*0.97 -> 0 | G13: =(E13+F13)*0.97 -> 0 | H13: =(B13+E13)*0.97 -> 0 | I13: =(C13+F13)*0.97 -> 0 | J13: =H13+I13 -> 0 | L13: =J13+K13 -> 0 | O13: =(M13+N13)*0.97 -> 0 | P13: =O13+L13 -> 0 | S13: Agosto | V13: =T13+U13 -> 0 | X13: Agosto | Y13: =D13*0.03 -> 0 | Z13: =G13*0.03 -> 0 | AA13: =O13*0.03 -> 0 | AB13: =Y13+Z13+AA13 -> 0 | AP13: =SUM(AP6:AP12) -> 2779130.3 | AS13: =SUM(AS6:AS12) -> 2791156.4
A14: Setembro | D14: =(B14+C14)*0.97 -> 0 | G14: =(E14+F14)*0.97 -> 0 | H14: =(B14+E14)*0.97 -> 0 | J14: =H14+I14 -> 0 | L14: =J14+K14 -> 0 | O14: =(M14+N14)*0.97 -> 0 | S14: Setembro | V14: =T14+U14 -> 0 | X14: Setembro | Y14: =D14*0.03 -> 0 | Z14: =G14*0.03 -> 0 | AA14: =O14*0.03 -> 0 | AB14: =Y14+Z14+AA14 -> 0 | AC14: CPA 8522700-26.2023.8.06.0000
A15: Outubro | D15: =(B15+C15)*0.97 -> 0 | G15: =(E15+F15)*0.97 -> 0 | H15: =((B15+E15)*0.97) -> 0 | I15: =C15+F15 -> 0 | J15: =H15+I15 -> 0 | L15: =J15+K15 -> 0 | O15: =(M15+N15)*0.97 -> 0 | P15: =383030.9-383029.56 -> 1.34 | S15: Outubro | V15: =T15+U15 -> 0 | X15: Outubro | Y15: =D15*0.03 -> 0 | Z15: =G15*0.03 -> 0 | AA15: =O15*0.03 -> 0 | AB15: =Y15+Z15+AA15 -> 0 | AC15: CPA 8525398-05.2023.8.06.0000
A16: Novembro | D16: =(B16+C16)*0.97 -> 0 | G16: =(E16+F16)*0.97 -> 0 | H16: =(B16+E16)*0.97 -> 0 | I16: =C16+F16 -> 0 | J16: =H16+I16 -> 0 | L16: =J16+K16 -> 0 | O16: =(M16+N16)*0.97 -> 0 | P16: =11170141.21-D16-G16 -> 11170141 | S16: Novembro | V16: =T16+U16 -> 0 | X16: Novembro | Y16: =D16*0.03 -> 0 | Z16: =G16*0.03 -> 0 | AA16: =O16*0.03 -> 0 | AB16: =Y16+Z16+AA16 -> 0
A17: Dezembro | D17: =(B17+C17)*0.97 -> 0 | G17: =(E17+F17)*0.97 -> 0 | H17: =B17+E17 -> 0 | I17: =C17+F17 -> 0 | J17: =H17+I17 -> 0 | L17: =J17+K17 -> 0 | O17: =(M17+N17)*0.97 -> 0 | S17: Dezembro | V17: =T17+U17 -> 0 | X17: Dezembro | Y17: 119366.06 | Z17: =G17*0.03 -> 0 | AA17: =O17*0.03 -> 0 | AB17: =Y17+Z17+AA17 -> 119366.06
A18: Total | B18: =SUM(B6:B17) -> 34258613 | C18: =SUM(C6:C17) -> 124361.19 | D18: =SUM(D6:D17) -> 33354136 | E18: =SUM(E6:E17) -> 29038.81 | F18: =SUM(F6:F17) -> 0 | G18: =SUM(G6:G17) -> 28167.646 | H18: =SUM(H6:H17) -> 18879679 | I18: =SUM(I6:I17) -> 120630.35 | ... O18: =SUM(O6:O17) -> 860655.69 | T18: =SUM(T6:T17) -> 393761.98 | U18: =SUM(U6:U17) -> 906.6 | V18: =T18+U18 -> 394668.58 | Y18: =SUM(Y6:Y17) -> 1119990.1 | Z18: =SUM(Z6:Z17) -> 845.02937 | AA18: =SUM(AA6:AA17) -> 25819.671 | AB18: =Z18+AA18 -> 26664.7
C20: =C6*0.03 -> 1167.4686 | D20: =D16*0.03 -> 0 | E20: =M18/B18 -> 0.025654465 | G20: =G16*0.03 -> 0 | J20: =13294818.44-13292817 -> 2001.44 | M20: =M6*0.03 -> 13546.687 | O20: =101256.36-101255.58 -> 0.78 | S20: dez | T20: 323451.91
B21: =B119*0.2 -> 10633.852 | C21: =B20+B21+C20 -> 11801.321 | P21: =9962239.47*0.03 -> 298867.18
A22: EMOLUMENTOS E CUSTAS EXTRAJUDICIAIS 2023
B23: FERMOJU | E23: DÉBITOS DE CORREIÇÃO | H23: TOTAL EXTRAJUDICIAIS | M23: VENDA DE SELOS
B24: RECEIITA 1122010198 | M24: RECEITA 1122010137 | Y24: TED
A25: MÊS | B25: DAES | C25: REJEITADOS | D25: TOTAL | E25: DAES | F25: REJEITADOS | G25: TOTAL | H25: DAES | I25: REJEITADOS | J25: SUB-TOTAL | K25: AJUSTE | L25: TOTAL | M25: DAES | N25: REJEITADOS | O25: TOTAL | U25: 32475.48 | X25: Janeiro | Y25: 0
A26: Janeiro | B26: 3605842.1 | C26: 2085.27 | D26: =B26+C26 -> 3607927.4 | G26: =E26+F26 -> 0 | H26: =B26+E26 -> 3605842.1 | I26: =C26+F26 -> 2085.27 | J26: =H26+I26 -> 3607927.4 | L26: =J26+K26 -> 3607927.4 | M26: 3271813.6 | N26: 8427.1 | O26: =M26+N26 -> 3280240.7 | P26: =M26/B26 -> 0.90736462 | Q26: =2927615.36-M26 -> -344198.22 | X26: Fevereiro
A27: Fevereiro | B27: 3654938 | C27: 1026.27 | D27: =B27+C27 -> 3655964.2 | G27: =E27+F27 -> 0 | H27: =B27+E27 -> 3654938 | I27: =C27+F27 -> 1026.27 | J27: =H27+I27 -> 3655964.2 | L27: =J27+K27 -> 3655964.2 | M27: 3407476.4 | N27: 721.45 | O27: =M27+N27 -> 3408197.9 | P27: =M27/B27 -> 0.93229391 | Q27: =O27*0.85 -> 2896968.2 | T27: 555843.19 | X27: Março
A28: Março | B28: 2124459.4 | D28: =B28+C28 -> 2124459.4 | E28: 0 | G28: =E28+F28 -> 0 | H28: =B28+E28 -> 2124459.4 | I28: =C28+F28 -> 0 | J28: =H28+I28 -> 2124459.4 | L28: =J28+K28 -> 2124459.4 | M28: 1955565.8 | O28: =M28+N28 -> 1955565.8 | P28: =M28/B28 -> 0.92050042 | Q28: =O28*0.85 -> 1662230.9 | T28: 370337.28 | X28: Abril
A29: Abril | D29: =B29+C29 -> 0 | G29: =E29+F29 -> 0 | H29: =B29+E29 -> 0 | I29: =C29+F29 -> 0 | J29: =H29+I29 -> 0 | L29: =J29+K29 -> 0 | O29: =M29+N29 -> 0 | P29: =M29/B29 -> #DIV/0! | Q29: =O29*0.85 -> 0 | T29: 132 | X29: Maio
A30: Maio | D30: =B30+C30 -> 0 | G30: =E30+F30 -> 0 | H30: =B30+E30 -> 0 | I30: =C30+F30 -> 0 | J30: =H30+I30 -> 0 | L30: =J30+K30 -> 0 | O30: =M30+N30 -> 0 | P30: =M30/B30 -> #DIV/0! | Q30: =O30*0.85 -> 0 | T30: 264.01 | X30: Junho
A31: Junho | D31: =B31+C31 -> 0 | G31: =E31+F31 -> 0 | H31: =B31+E31 -> 0 | I31: =C31+F31 -> 0 | J31: =H31+I31 -> 0 | O31: =M31+N31 -> 0 | P31: =M31/B31 -> #DIV/0! | T31: 3004 | X31: Julho | AA31: =462263.53+562.7+3730.74 -> 466556.97
A32: Julho | D32: =B32+C32 -> 0 | G32: =E32+F32 -> 0 | H32: =B32+E32 -> 0 | I32: =C32+F32 -> 0 | J32: =H32+I32 -> 0 | L32: =J32+K32 -> 0 | O32: =M32+N32 -> 0 | P32: =M32/B32 -> #DIV/0! | Q32: =9800/4 -> 2450 | S32: =2200/20 -> 110 | T32: =SUM(T27:T31) -> 929580.48 | X32: Agosto
A33: Agosto | D33: =B33+C33 -> 0 | G33: =E33+F33 -> 0 | H33: =B33+E33 -> 0 | I33: =C33+F33 -> 0 | J33: =H33+I33 -> 0 | L33: =J33+K33 -> 0 | O33: =M33+N33 -> 0 | P33: =M33/B33 -> #DIV/0!
A34: Setembro | D34: =B34+C34 -> 0 | G34: =E34+F34 -> 0 | H34: =B34+E34 -> 0 | I34: =C34+F34 -> 0 | J34: =H34+I34 -> 0 | L34: =J34+K34 -> 0 | O34: =M34+N34 -> 0 | P34: =M34/B34 -> #DIV/0!
A35: Outubro | D35: =B35+C35 -> 0 | G35: =E35+F35 -> 0 | H35: =B35+E35 -> 0 | I35: =C35+F35 -> 0 | J35: =H35+I35 -> 0 | L35: =J35+K35 -> 0 | O35: =M35+N35 -> 0 | P35: =M35/B35 -> #DIV/0! | T35: =86*431.32 -> 37093.52
A36: Novembro | D36: =B36+C36 -> 0 | G36: =E36+F36 -> 0 | H36: =B36+E36 -> 0 | I36: =C36+F36 -> 0 | J36: =H36+I36 -> 0 | L36: =J36+K36 -> 0 | O36: =M36+N36 -> 0 | Q36: =70/170 -> 0.41176471
A37: Dezembro | D37: =B37+C37 -> 0 | G37: =E37+F37 -> 0 | H37: =B37+E37 -> 0 | I37: =C37+F37 -> 0 | J37: =H37+I37 -> 0 | L37: =J37+K37 -> 0 | O37: =M37+N37 -> 0
A38: Total | B38: =SUM(B26:B37) -> 9385239.5 | D38: =B38+C38 -> 9385239.5 | E38: =SUM(E26:E37) -> 0 | F38: =SUM(F26:F37) -> 0 | G38: =E38+F38 -> 0 | H38: =B38+E38 -> 9385239.5 | I38: =C38+F38 -> 0 | J38: =H38+I38 -> 9385239.5 | L38: =J38+K38 -> 9385239.5 | M38: =SUM(M26:M37) -> 8634855.8 | N38: =SUM(N26:N37) -> 9148.55 | O38: =M38+N38 -> 8644004.3 | AH38: =AH45-AE45-J45 -> 28033
A41: SERVIÇOS PRESTADOS PELO FERMOJU
B42: TARIFA DE INSCRIÇÕES EM CONCURSOS | E42: RECEITA SOBRE A VENDA DE LIVROS | H42: DISTRIBUIÇÃO DE TÍTULOS PARA PROTESTO | K42: SERVIÇOS DE COMUNICAÇÃO | N42: DIÁRIO DA JUSTIÇA | Q42: SUBTOTAL OUTROS SERVIÇOS DE COMUNICAÇÃO | T42: ESMEC (SERVIÇOS EDUCACIONAIS) | W42: CRECHE | Z42: ENVIO DE SELOS VIA PAC | AC42: OUTROS SERVIÇOS (CRECHE + ENVIO DE SELOS VIA PAC) | AF42: TOTAL SERVIÇOS PRESTADOS PELO FERMOJU
B43: RECEITA 1611020101 | E43: RECEITA 1611010107 | T43: 1611010116 | W43: 1611010199
A44: MÊS | B44: DAES | C44: REJEITADOS | D44: TOTAL | E44: DAES | F44: REJEITADOS | G44: TOTAL | H44: DAES | I44: REJEITADOS | J44: TOTAL | K44: DAES | L44: REJEITADOS | M44: TOTAL | N44: DAES | O44: REJEITADOS | P44: TOTAL | Q44: DAES | R44: REJEITADOS | S44: TOTAL | T44: DAES | U44: REJEITADOS | V44: TOTAL | W44: DAES | X44: REJEITADOS | Y44: TOTAL | Z44: DAES | AA44: REJEITADOS | AB44: TOTAL | AC44: DAES | AD44: REJEITADOS | AE44: TOTAL | AF44: DAES | AG44: REJEITADOS | AH44: TOTAL
...

Sheet 1. CONSOLIDAÇÃO_MENSAL 2024
B1: ARRECADAÇÃO MENSAL POR PRODUTO DE RECEITA
B2: ARRECADAÇÃO FERMOJU – EXERCÍCIO 2025 – ATUALIZADO ATÉ 20/03/2025
B3: 101 | C3: JANEIRO | D3: FEVEREIRO | E3: MARÇO | F3: ABRIL | G3: MAIO | H3: JUNHO | I3: JULHO | J3: AGOSTO | K3: SETEMBRO | L3: OUTUBRO | M3: NOVEMBRO | N3: DEZEMBRO | O3: TOTAL | P3: % ACUMULADO / RECEITA TOTAL | Q3: PREVISAÕ ATUALIZADA | R3: PREVISÃO PARA 2024 COM IPCA PROJETADO DE 6,03% | Y3: SETEMBRO
B4: DAEs (VALORES EM R$)
A5: DAES | B5: CUSTAS PROCESSUAIS | C5: 11780457 | D5: 12109082 | E5: 13062127 | F5: 13959120 | G5: 13995098 | H5: 13264397 | I5: 15825878 | J5: 12991709 | K5: 13597879 | L5: 14551598 | M5: 11155622 | N5: 10013566 | O5: 1.5630653e+08 | P5: =O5/$O$39 -> 0.45798691 | Q5: 116624035 | R5: =O5*1.0603 -> 1.6573182e+08 | Y5: 13597879
B6: CUSTAS JUDICIAIS RECUPERADAS | C6: 2818.1 | D6: 10275.5 | E6: 7852.41 | F6: 24253.31 | G6: 20649.47 | H6: 30421.63 | I6: 9795.58 | J6: 15114.88 | K6: 30839.07 | L6: 22930.96 | M6: 14519.08 | N6: 7451.75 | O6: 196921.75 | P6: =O6/$O$39 -> 0.00057699177 | R6: =O6*1.0603 -> 208796.13 | Y6: 30839.074
B7: CUSTAS JUDICIAIS DÍVIDA ATIVA | C7: 130457.85 | D7: 112262.44 | E7: 209783.92 | F7: 238511.48 | G7: 71177.91 | H7: 251202.18 | I7: 208056.08 | J7: 488620.59 | K7: 101256.36 | L7: 383030.9 | M7: 176408.38 | N7: 173676.08 | O7: 2544444.2 | P7: =O7/$O$39 -> 0.0074553642 | Q7: 270544 | R7: =O7*1.0603 -> 2697874.2 | Y7: 101256.36
B8: EMOLUMENTOS (FERMOJU) | C8: 3490715.3 | D8: 2836549.1 | E8: 3020622.3 | F8: 3575720.4 | G8: 3155811.1 | H8: 3313205.1 | I8: 4108847 | J8: 3355197 | K8: 3718894.7 | L8: 3988909.9 | M8: 3375838 | N8: 3944333.8 | O8: 41884644 | P8: =O8/$O$39 -> 0.12272436 | Q8: 30402110 | R8: =O8*1.0603 -> 44410288 | T8: =E8+E10-2880752.72 -> #VALUE! | U8: =G9*0.85 -> 2572904.2 | Y8: 3718894.7
B9: VENDA DE SELOS | C9: 3426628.1 | D9: 2823066 | E9: 2942060.5 | F9: 3387183.8 | G9: 3026946.1 | H9: 3086974.9 | I9: 3973940.8 | J9: 3270155.2 | K9: 3551091 | L9: 3784652.1 | M9: 3121376.4 | N9: 3489657.6 | O9: 39883732 | P9: =O9/$O$39 -> 0.11686157 | Q9: 35142102 | R9: =O9*1.0603 -> 42288721 | Y9: 3551091
B10: DÉBITOS DE CORREIÇÃO | C10: 7000 | D10: 7000 | E10: - | F10: - | H10: - | I10: - | J10: - | K10: - | L10: - | M10: - | N10: - | O10: 14000 | P10: =O10/$O$39 -> 4.1020785e-05 | R10: =O10*1.0603 -> 14844.2 | Y10: 0
B11: TARIFA DE INSCRIÇÃO EM CONCURSOS | C11: - | D11: - | E11: - | F11: - | H11: - | I11: - | J11: - | K11: - | L11: - | M11: - | N11: - | O11: - | P11: =O11/$O$39 -> #VALUE! | R11: =O11*1.0603 -> #VALUE! | Y11: 0
B12: RECEITA SOBRE A VENDA DE LIVROS | C12: - | D12: - | E12: - | F12: - | H12: - | I12: - | J12: - | K12: - | L12: - | M12: - | N12: - | O12: - | P12: =O12/$O$39 -> #VALUE! | R12: =O12*1.0603 -> #VALUE! | Y12: 0
B13: ESMEC | C13: - | D13: - | E13: - | F13: - | H13: - | I13: - | J13: - | K13: - | L13: - | O13: - | P13: =O13/$O$39 -> #VALUE! | R13: =O13*1.0603 -> #VALUE! | Y13: 0
B14: SERVIÇOS DE COMUNICAÇÃO | C14: - | D14: - | E14: - | F14: - | H14: - | I14: - | J14: - | K14: - | L14: - | M14: - | N14: - | O14: - | P14: =O14/$O$39 -> #VALUE! | R14: =O14*1.0603 -> #VALUE! | Y14: 0
B15: DIÁRIO DA JUSTIÇA | C15: 45619.75 | D15: 84678.85 | E15: 69127.54 | F15: 69587.22 | G15: 74754.25 | H15: 57726.45 | I15: 62563.37 | J15: 73732.29 | K15: 50410.2 | L15: 77718.79 | M15: 45256.81 | N15: 35710.32 | O15: 746885.84 | P15: =O15/$O$39 -> 0.0021884174 | R15: =O15*1.0603 -> 791923.06 | Y15: 50410.2
B16: CRECHE | C16: - | D16: 31037.95 | E16: 44686.06 | F16: 37075.82 | G16: 28676.58 | H16: 29675.34 | I16: 35758.11 | J16: 31812.13 | K16: 40391.22 | L16: 30464.87 | M16: 28676.58 | N16: 66487.4 | O16: 404742.06 | P16: =O16/$O$39 -> 0.0011859169 | R16: =O16*1.0603 -> 429148.01 | W16: =35/95 -> 0.36842105 | Y16: 40391.22
B17: DISTRIBUIÇÃO DE TÍTULOS PARA PROTESTO | C17: - | D17: - | E17: - | F17: - | H17: - | I17: - | J17: - | K17: - | L17: - | M17: - | N17: - | O17: - | P17: =O17/$O$39 -> #VALUE! | R17: =O17*1.0603 -> #VALUE! | W17: 58 | Y17: 0
B18: ENVIO DE SELOS VIA PAC | C18: 2093.6 | D18: 1423.68 | E18: 1537.32 | F18: 1817.56 | G18: 1913.32 | H18: 2396.14 | I18: 2302.65 | J18: 2000.13 | K18: 2267.01 | L18: 1936.78 | M18: 2202.13 | N18: 2762.48 | O18: 22652.67 | P18: =O18/$O$39 -> 6.6373594e-05 | R18: =O18*1.0603 -> 24018.626 | W18: =W17/W16 -> 157.42857 | Y18: 2267.01
B19: ALIENAÇÃO DE IMÓVEIS RURAIS | C19: - | D19: - | E19: - | F19: - | H19: - | I19: - | J19: - | K19: - | L19: - | M19: - | N19: - | O19: - | P19: =O19/$O$39 -> #VALUE! | R19: =O19*1.0603 -> #VALUE! | Y19: 0
B20: ALIENAÇÃO DE IMÓVEIS URBANOS | C20: - | D20: - | E20: - | F20: - | H20: - | I20: - | J20: - | K20: - | L20: - | M20: - | N20: - | O20: - | P20: =O20/$O$39 -> #VALUE! | R20: =O20*1.0603 -> #VALUE! | Y20: 0
B21: ALIENAÇÃO DE BENS MÓVEIS | C21: 2777.39 | D21: - | E21: - | F21: - | H21: - | I21: - | J21: - | K21: - | L21: - | M21: - | N21: - | O21: 2777.39 | P21: =O21/$O$39 -> 8.1379085e-06 | R21: =O21*1.0603 -> 2944.8666 | Y21: 0
B22: RESTITUIÇÃO DE EXCEDENTES AO TETO + OUTRAS RESTITUICOES | C22: 1726750.7 | D22: 978537.31 | E22: 1002713.3 | F22: 1042934 | G22: 1490709 | H22: 1027414.2 | I22: 1269226.5 | J22: 1357326.8 | K22: 1544027.1 | L22: 1364599.6 | M22: 1551400.6 | N22: 1316823.5 | O22: 15672463 | P22: =O22/$O$39 -> 0.045921195 | R22: =O22*1.0603 -> 16617512 | S22: =320/9 -> 35.555556 | Y22: 1544027.1
B23: INDENIZAÇÕES DIVERSAS | C23: - | D23: - | E23: - | F23: 12667.61 | G23: 240.23 | H23: - | I23: - | J23: - | K23: 39824.74 | L23: 2206.66 | M23: 1695.83 | N23: 2630.86 | O23: 59265.93 | P23: =O23/$O$39 -> 0.0001736525 | R23: =O23*1.0603 -> 62839.666 | Y23: 39824.74
B24: RESTITUIÇÕES DIVERSAS | C24: 359.33 | D24: 58.3 | E24: 135.35 | F24: 129.85 | G24: - | H24: 667.15 | I24: - | J24: 559.77 | K24: 97.26 | L24: - | M24: 624.25 | N24: 1401.02 | O24: 4032.28 | P24: =O24/$O$39 -> 1.1814807e-05 | R24: =O24*1.0603 -> 4275.4265 | Y24: 97.26
B25: ALUGUÉIS | C25: 46855.12 | D25: 46017.01 | E25: 910.91 | F25: 87228.67 | G25: 44800.21 | H25: 44754.21 | I25: 983.71 | J25: 44754.21 | K25: 88451.91 | L25: 44411.13 | M25: 44411.13 | N25: 43446.33 | O25: 537024.57 | P25: =O25/$O$39 -> 0.0015735121 | R25: =O25*1.0603 -> 569407.15 | Y25: 88451.91
B26: RECEITAS EVENTUAIS | C26: 188779.54 | D26: 206435.54 | E26: 193707.8 | F26: 233993.67 | G26: 256854.21 | H26: 190959.13 | I26: 224369.89 | J26: 256532.71 | K26: 177272.12 | L26: 173951.38 | M26: 143628.81 | N26: 143801.96 | O26: 2390286.8 | P26: =O26/$O$39 -> 0.0070036743 | R26: =O26*1.0603 -> 2534421.1 | Y26: 177272.12
B27: MULTAS CONTRATUAIS | C27: - | D27: - | E27: - | F27: - | H27: - | I27: - | J27: - | K27: - | L27: - | M27: - | O27: - | P27: =O27/$O$39 -> #VALUE! | R27: =O27*1.0603 -> #VALUE! | Y27: 0
B28: MULTAS JUDICIAIS | C28: 7728.87 | D28: 36071.92 | E28: 29868.92 | F28: 19060.43 | G28: 59707.89 | H28: 29440.69 | I28: 68810.92 | J28: 18666.47 | K28: 13756.32 | L28: 17204.8 | M28: 67159.22 | N28: 4864.14 | O28: 372340.59 | P28: =O28/$O$39 -> 0.0010909788 | R28: =O28*1.0603 -> 394792.73 | Y28: 13756.32
B29: =SUM(B5:B28) -> 0 | C29: =SUM(C5:C28) -> 20859041 | D29: =SUM(D5:D28) -> 19282496 | E29: =SUM(E5:E28) -> 20585133 | F29: =SUM(F5:F28) -> 22689284 | G29: =SUM(G5:G28) -> 22227338 | H29: =SUM(H5:H28) -> 21329234 | I29: =SUM(I5:I28) -> 25790532 | ... N29: =SUM(N5:N28) -> 19246614 | O29: =SUM(C29:N29) -> 2.6104475e+08 | P29: =SUM(P5:P28) -> #VALUE! | R29: =SUM(D29:O29) -> 5.0123045e+08 | Y29: 22956458
A30: 2339
A31: RENDIMENTOS | B31: RENDIMENTOS FONTE 29 | C31: 232077.88 | D31: 206614.09 | E31: 213349.76 | F31: 231921.38 | G31: 219691.81 | H31: 206363.86 | I31: 233548.43 | J31: 231308.7 | K31: 216602.86 | L31: 241522.21 | M31: 211924.9 | N31: 233904.97 | O31: =SUM(C31:N31) -> 2678830.8 | P31: =O31/$O$39 -> 0.0078491247 | R31: =O31*1.0603 -> 2840364.4 | T31: =O31/5 -> 535766.17 | Y31: 216602.86
B32: RENDIMENTOS FONTE 70 | C32: 3018833.9 | D32: 2618540.3 | E32: 2782265.4 | F32: 2991970.9 | G32: 2841486.9 | H32: 2761663 | I32: 3244076.8 | J32: 3176849.1 | K32: 3099667.2 | L32: 3526724.5 | M32: 2991512.8 | N32: 3179641.2 | O32: =SUM(C32:N32) -> 36233232 | P32: =O32/$O$39 -> 0.1061654 | R32: =O32*1.0603 -> 38418096 | T32: =O32/5 -> 7246646.4 | Y32: 3099667.2
B33: SPREAD DEPÓSITOS JUDICIAIS | C33: 2004212.4 | D33: 2061569.1 | E33: 2122616.7 | F33: 2161686.1 | G33: 2008649.8 | H33: 2031871.9 | I33: 2133207.7 | J33: 2232968.5 | K33: 2285790 | L33: 2307247.6 | M33: 2404403.9 | N33: 4611869 | O33: =SUM(C33:N33) -> 28366093 | P33: =O33/$O$39 -> 0.083114243 | R33: =O33*1.0603 -> 30076568 | T33: =O33/5 -> 5673218.6 | Y33: 2285790
B34: SPREAD PRECATÓRIOS | C34: 586661.43 | D34: 622750.37 | E34: 621785.24 | F34: 689907.32 | G34: 708049.05 | H34: 725266.34 | I34: 730801.22 | J34: 696518.27 | K34: 691398.6 | L34: 619249.58 | M34: 611996.13 | N34: 615353.76 | O34: =SUM(C34:N34) -> 7919737.3 | P34: =O34/$O$39 -> 0.023205275 | R34: =O34*1.0603 -> 8397297.5 | T34: =O34/5 -> 1583947.5 | Y34: 691398.6
B35: SPREAD FIANÇAS | D35: 486789.49 | E35: 1008815.3 | F35: 411076.53 | G35: 0 | H35: 385584.32 | I35: 673945.01 | J35: 469830.73 | L35: 799611.19 | M35: 484676.92 | N35: 329425.12 | O35: =SUM(C35:N35) -> 5049754.6 | P35: =O35/$O$39 -> 0.014796064
B36: TOTAL RENDIMENTOS | C36: =SUM(C31:C35) -> 5841785.6 | D36: =SUM(D31:D35) -> 5996263.3 | E36: =SUM(E31:E35) -> 6748832.4 | F36: =SUM(F31:F35) -> 6486562.2 | G36: =SUM(G31:G35) -> 5777877.6 | H36: =SUM(H31:H35) -> 6110749.4 | I36: =SUM(I31:I35) -> 7015579.2 | J36: =SUM(J31:J35) -> 6807475.4 | ... P36: =SUM(P31:P35) -> 0.23513011 | R36: =SUM(D36:O36) -> 1.5465351e+08 | Y36: 6293458.7
B38: CONSOLIDADO: DAEs + RENDIMENTOS (VALORES EM R$)
B39: TOTAL CONSOLIDADO | C39: =C29+C36 -> 26700826 | D39: =D29+D36 -> 25278759 | E39: =E29+E36 -> 27333966 | F39: =F29+F36 -> 29175846 | G39: =G29+G36 -> 28005215 | H39: =H29+H36 -> 27439983 | I39: =I29+I36 -> 32806111 | J39: =J29+J36-J18 -> 28711657 | K39: =K29+K36 -> 29249916 | L39: =L29+L36 -> 31937971 | M39: =M29+M36 -> 26433334 | N39: =N29+N36 -> 28216808 | O39: =SUM(C39:N39)+0.01 -> 3.4129039e+08 | P39: =P29+P36 -> #VALUE! | R39: =SUM(D39:O39) -> 6.5587996e+08 | V39: =(150000000-O39)/13 -> -14714646 | Y39: 29249916
C40: =C29+C44+C45+'1__POR_RECEITA_DETALHADA'!T6+'1__POR_RECEITA_DETALHADA'!B150 -> 23108502
C41: =C29+'1__POR_RECEITA_DETALHADA'!Q6+'1__POR_RECEITA_DETALHADA'!Q7+'1__POR_RECEITA_DETALHADA'!B138 -> 22714740 | D41: =D39-15072842.32 -> 10205917 | G41: =C5*0.97 -> 11427043 | I41: =13006824.2-J5-J6 -> -1.0422809e-09 | J41: =28711656.65-J39 -> 0 | K41: = | L41: =L39-31864595.28 -> 73376.04 | O41: =14/5 -> 2.8
...

Sheet Planilha1
A1: RECEITAS FERMOJU - ARRECADAÇÃO BRUTA MENSAL ATÉ 07/04/2025
B2: ANO DE ARRECADAÇÃO | G2: VARIAÇÃO | L2: PROJEÇÕES ATUALIZADAS EM 20.03.2025
A3: ANO | B3: 2021 | C3: 2022 | D3: 2023 | E3: 2024 | F3: 2025 | G3: 2022 x 2021 | H3: 2023 x 2022 | I3: 2024 X 2022 | J3: 2024 X 2023 | K3: 2025 X 2024
A4: Janeiro | B4: 11024672 | C4: 15261167 | D4: 26688876 | E4: 26700826 | F4: 31663203 | G4: =C4/B4-1 -> 0.38427394 | H4: =D4/C4-1 -> 0.7488097 | I4: =E4/C4-1 -> 0.74959272 | J4: =E4/D4-1 -> 0.00044774459 | K4: =SUM(F4/E4)-1 -> 0.18585108 | L4: PARA MARÇO/2025:
A5: Fevereiro | B5: 12279375 | C5: 17055894 | D5: 23915418 | E5: 25278759 | F5: 36234389 | G5: =C5/B5-1 -> 0.3889872 | H5: =D5/C5-1 -> 0.40217909 | I5: =E5/C5-1 -> 0.48211283 | J5: =E5/D5-1 -> 0.057006797 | K5: =F5/E5-1 -> 0.43339271 | L5: =F6 -> 32143077
A6: Março | B6: 13134102 | C6: 22507411 | D6: 27582188 | E6: 27333966 | F6: 32143077 | G6: =C6/B6-1 -> 0.71366191 | H6: =D6/C6-1 -> 0.2254714 | I6: =E6/C6-1 -> 0.21444293 | J6: =E6/D6-1 -> -0.0089993712 | K6: =F6/E6-1 -> 0.17593902
A7: Abril | B7: 11453234 | C7: 18395784 | D7: 22562340 | E7: 29175846 | F7: 2352159.3 | G7: =C7/B7-1 -> 0.60616498 | H7: =D7/C7-1 -> 0.2264952 | I7: =E7/C7-1 -> 0.58600724 | J7: =E7/D7-1 -> 0.29312144 | K7: =SUM(F7/E7)-1 -> -0.91937991 | L7: COMPARATIVO: PROJEÇÃO MAR/25 X MAR/24
A8: Maio | B8: 13645685 | C8: 23800038 | D8: 28443400 | E8: 28005215 | G8: =C8/B8-1 -> 0.74414386 | H8: =D8/C8-1 -> 0.19509897 | I8: =E8/C8-1 -> 0.17668786 | J8: =E8/D8-1 -> -0.015405509
A9: Junho | B9: 14024558 | C9: 22055305 | D9: 28641986 | E9: 27439983 | G9: =C9/B9-1 -> 0.57262038 | H9: =D9/C9-1 -> 0.29864385 | I9: =E9/C9-1 -> 0.24414435 | J9: =E9/D9-1 -> -0.041966467
A10: Julho | B10: 14805106 | C10: 23094990 | D10: 28998692 | E10: 32806111 | G10: =C10/B10-1 -> 0.5599341 | H10: =D10/C10-1 -> 0.25562696 | I10: =E10/C10-1 -> 0.42048605 | J10: =E10/D10-1 -> 0.13129623 | L10: PARA O EXERCÍCIO 2025:
A11: Agosto | B11: 15960024 | C11: 26074003 | D11: 29865029 | E11: 28711657 | G11: =C11/B11-1 -> 0.63370703 | H11: =D11/C11-1 -> 0.14539487 | I11: =E11/C11-1 -> 0.10116029 | J11: =E11/D11-1 -> -0.038619506 | L11: ='[1]2_PROJEÇÕES_MARÇO-2025'!F45 -> 33664006
A12: Setembro | B12: 14690634 | C12: 22986159 | D12: 36462420 | E12: 29249916 | G12: =C12/B12-1 -> 0.56468122 | H12: =D12/C12-1 -> 0.5862772 | I12: =E12/C12-1 -> 0.27250125 | J12: =E12/D12-1 -> -0.1978065
A13: Outubro | B13: 14988969 | C13: 23856414 | D13: 28649494 | E13: 31937971 | G13: =C13/B13-1 -> 0.59159809 | H13: =D13/C13-1 -> 0.20091365 | I13: =E13/C13-1 -> 0.33875824 | J13: =E13/D13-1 -> 0.1147831 | L13: COMPARATIVO: PROJEÇÃO 2025 X REALIZAD0 2024
A14: Novembro | B14: 17295635 | C14: 22770509 | D14: 26013370 | E14: 26433334 | G14: =C14/B14-1 -> 0.3165466 | H14: =D14/C14-1 -> 0.14241492 | I14: =E14/C14-1 -> 0.16085827 | J14: =E14/D14-1 -> 0.016144177 | L14: =L11/E16-1 -> -0.90136257
A15: Dezembro | B15: 17563216 | C15: 21902322 | D15: 24781965 | E15: 28216808 | G15: =C15/B15-1 -> 0.24705646 | H15: =D15/C15-1 -> 0.13147658 | I15: =E15/C15-1 -> 0.28830209 | J15: =E15/D15-1 -> 0.13860253
A16: TOTAL | B16: =SUM(B4:B15) -> 1.7086521e+08 | C16: =SUM(C4:C15) -> 2.5976e+08 | D16: =SUM(D4:D15) -> 3.3260518e+08 | E16: =SUM(E4:E15) -> 3.4129039e+08 | F16: =SUM(F4:F15) -> 1.0239283e+08 | G16: =C16/B16-1 -> 0.52026264 | H16: =D16/C16-1 -> 0.28043265 | I16: =E16/C16-1 -> 0.31386818 | J16: =E16/D16-1 -> 0.026112685 | L16: RECEITA ACUMULADA EM 2025
A17: Média Mensal | B17: =B16/12 -> 14238768 | C17: =C16/12 -> 21646666 | D17: =D16/12 -> 27717098 | E17: =E16/12 -> 28440866 | F17: =F16/12 -> 8532735.7 | G17: =C17/B17-1 -> 0.52026264 | H17: =D17/C17-1 -> 0.28043265 | I17: =E17/C17-1 -> 0.31386818 | J17: =E17/D17-1 -> 0.026112685 | L17: =F16 -> 1.0239283e+08
A18: Fonte: SIAFE e AMBIENTE SEGURO (ambos SEFAZ) | L18: RECEITA ACUMULADA EM 2024 ATÉ FEVEREIRO
D19: ARRECADAÇÃO OBTIDA EM 2024 ATÉ NOVEMBRO (R$) | F19: META PARA 2024 (R$) | G19: ARRECADAÇÃO MENSAL NECESSÁRIA EM PARA ATINGIR A META | L19: =SUM(E4:E6) -> 79313551
D20: =SUM($G$4:$G$14) -> 6.0763193 | F20: 350000000 | G20: =F20-D20 -> 3.4999999e+08 | L20: EVOLUÇÃO 1º TRIMESTRE 2025 X 1º TRIMESTRE 2024
D21: =SUM($G$4:$G$14) -> 6.0763193 | F21: =F20-2000000 -> 348000000 | G21: =F21-D21 -> 3.4799999e+08 | L21: =L17/L19-1 -> 0.29098783
D22: =SUM($G$4:$G$14) -> 6.0763193 | F22: =F21-2000000 -> 346000000 | G22: =F22-D22 -> 3.4599999e+08
D23: =SUM($G$4:$G$14) -> 6.0763193 | F23: =F22-2000000 -> 344000000 | G23: =F23-D23 -> 3.4399999e+08 | L23: DESCONSIDERANDO CERCA DE R$ 9.000.000,00 DE FIANÇA ACUMULADA EM 2023 CONTABILIZADA NA RECEITA DE SET/2023
D24: =SUM($G$4:$G$14) -> 6.0763193 | F24: =F23-2000000 -> 342000000 | G24: =F24-D24 -> 3.4199999e+08 | L24: RECEITA ACUMULADA EM 2024 MENOS R$ 9.000.000,00
D25: =SUM($G$4:$G$14) -> 6.0763193 | F25: =F24-2000000 -> 340000000 | G25: =F25-D25 -> 3.3999999e+08 | L25: =L17-9000000 -> 93392829
L27: COMPARATIVO: ACUMULADO 2024 X 2023
F28: =26433583.89-26433333.98 -> 249.91 | L28: =L19/L25-1 -> -0.15075331

Sheet CONSOLIDAÇÃO MENSAL FERMOJU 202
B1: ARRECADAÇÃO MENSAL POR PRODUTO DE RECEITA – ARRECADAÇÃO FERMOJU – EXERCÍCIO 2026
C3: JANEIRO | D3: FEVEREIRO | E3: MARÇO | F3: ABRIL | G3: MAIO | H3: JUNHO | I3: JULHO | J3: AGOSTO | K3: AMB SEGU | L3: SETEMBRO | M3: OUTUBRO | N3: NOVEMBRO | O3: DEZEMBRO | P3: TOTAL | Q3: % ACUMULADO / RECEITA TOTAL
B4: DAEs (VALORES EM R$)
A5: / | B5: 62950- CUSTAS PROCESSUAIS | C5: 12132542 | D5: 14095018 | E5: 17211344 | F5: 17227005 | G5: 17722596 | H5: 19322804 | I5: 19765793 | J5: 17989998 | K5: 19245856 | P5: =SUM(C5+D5+E5+F5+G5+H5+I5+J5) -> 1.354671e+08 | Q5: =P5/$P$42 -> 0.37027083
B6: 62975- CUSTAS JUDICIAIS RECUPERADAS | C6: 123.44 | D6: 559.06 | E6: 15966.32 | F6: 12850.2 | G6: 36240.74 | H6: 17925.72 | I6: 3181.1 | J6: 9931.26 | K6: 10238.37 | P6: =SUM(C6+D6+E6+F6+G6+H6+I6+J6) -> 96777.84 | Q6: =P6/$P$42 -> 0.00026452187
B7: 63531- RECEITA DA DIVIDA ATIVA DE CUSTOS JUDICIAIS | C7: 121669.9 | D7: 84458.06 | E7: 455638.39 | F7: 107559.12 | G7: 112897.31 | H7: 156731.15 | I7: 146816.23 | J7: 104509.19 | K7: 135244.73 | P7: =SUM(C7+D7+E7+F7+G7+H7+I7+J7) -> 1290279.4 | Q7: =P7/$P$42 -> 0.0035267073
B8: 62948- OUTROS EMOLUMENTOS E CUSTAS EXTRA JUDICIAIS | C8: 3825622 | D8: 3689474.8 | E8: 4767496.8 | F8: 3803868.1 | G8: 4440325.9 | H8: 4999301.1 | I8: 4464736.7 | J8: 4496707.3 | K8: 4532154.3 | P8: =SUM(C8+D8+E8+F8+G8+H8+I8+J8) -> 34487533 | Q8: =P8/$P$42 -> 0.094264418
B9: 62947- VENDA DE SELOS DE AUTENTICIDADE | C9: 3341162.7 | D9: 3135505 | E9: 4178974.3 | F9: 3172814.2 | G9: 3899224.8 | H9: 4312644.9 | I9: 3879523.4 | J9: 3896145.1 | K9: 3886503.5 | P9: =SUM(C9+D9+E9+F9+G9+H9+I9+J9) -> 29815994 | Q9: =P9/$P$42 -> 0.081495751
B10: 62949- DEBITOS DE CORREIÇÃO | P10: =SUM(C10+D10+E10+F10+G10+H10+I10+J10) -> 0 | Q10: =P10/$P$42 -> 0
B11: 62956- TARIFA DE INSCRIÇÃO EM CONCURSOS | G11: 655851 | H11: 4420260 | I11: -8670 | P11: =SUM(C11+D11+E11+F11+G11+H11+I11+J11) -> 5067441 | Q11: =P11/$P$42 -> 0.013850784
B12: 62957- RECEITA SOBRE A VENDA DE LIVROS | P12: =SUM(C12+D12+E12+F12+G12+H12+I12+J12) -> 0 | Q12: =P12/$P$42 -> 0
B13: 62958- ESMEC | P13: =SUM(C13+D13+E13+F13+G13+H13+I13+J13) -> 0 | Q13: =P13/$P$42 -> 0
B14: 62959- SERVIÇOS DE COMUNICAÇÃO | P14: =SUM(C14+D14+E14+F14+G14+H14+I14+J14) -> 0 | Q14: =P14/$P$42 -> 0
B15: 62960- VENDA DE DIARIO | I15: 169.56 | P15: =SUM(C15+D15+E15+F15+G15+H15+I15+J15) -> 169.56 | Q15: =P15/$P$42 -> 4.634566e-07
B16: 62967- SERVICOS ADMINISTRATIVOS E COMERCIAIS GERAIS-CRECHE | C16: 8799.4 | D16: 52675.42 | E16: 35535.03 | F16: 32575.28 | G16: 45163.06 | H16: 45163.06 | I16: 33353.9 | J16: 34218.06 | K16: 34218.06 | P16: =SUM(C16+D16+E16+F16+G16+H16+I16+J16) -> 287483.21 | Q16: =P16/$P$42 -> 0.0007857749
B17: 62970- DISTRIBUIÇÃO DE TÍTULOS PARA PROTESTO | P17: =SUM(C17+D17+E17+F17+G17+H17+I17+J17) -> 0 | Q17: =P17/$P$42 -> 0
B18: 62973- SERVICOS ADMINISTRATIVOS E COMERCIAIS GERAIS – SELOS PAC | C18: 691.78 | D18: 724.5 | E18: 187.78 | P18: =SUM(C18+D18+E18+F18+G18+H18+I18+J18) -> 1604.06 | Q18: =P18/$P$42 -> 4.3843607e-06
B19: ALIENAÇÃO DE IMÓVEIS RURAIS | P19: =SUM(C19+D19+E19+F19+G19+H19+I19+J19) -> 0 | Q19: =P19/$P$42 -> 0
B20: ALIENAÇÃO DE IMÓVEIS URBANOS | C20: 314.94 | P20: =SUM(C20+D20+E20+F20+G20+H20+I20+J20) -> 314.94 | Q20: =P20/$P$42 -> 8.6082226e-07
B21: RECEITA DE CESSAO DE DIREITO DE OPERACIONALIZACAO DA FOPAG | P21: =SUM(C21+D21+E21+F21+G21+H21+I21+J21) -> 0
B22: 62969- ALIENAÇÃO DE BENS MÓVEIS ALIENACAO DE BENS MOVEIS E SEMOVENTES | P22: =SUM(C22+D22+E22+F22+G22+H22+I22+J22) -> 0 | Q22: =P22/$P$42 -> 0
B23: 63320- RESTITUIÇÃO DE EXCEDENTES AO TETO + OUTRAS RESTITUICOES | C23: 3849029.5 | D23: 3309462.1 | E23: 2335751.3 | F23: 2769193.4 | G23: 3492059.3 | H23: 3661550.2 | I23: 2676218.4 | J23: 3206290.2 | K23: 4106290.2 | P23: =SUM(C23+D23+E23+F23+G23+H23+I23+J23) -> 25299555 | Q23: =P23/$P$42 -> 0.069151012
B24: 62963- INDENIZAÇÕES DIVERSAS | C24: 97.74 | D24: 5810.3 | E24: 3910.5 | F24: 5227.44 | G24: 10184.88 | H24: 1407.65 | I24: 536.6 | J24: 1073.2 | K24: 1073.2 | P24: =SUM(C24+D24+E24+F24+G24+H24+I24+J24) -> 28248.31 | Q24: =P24/$P$42 -> 7.7210815e-05
B25: 62964- RESTITUIÇÕES DIVERSAS | P25: =SUM(C25+D25+E25+F25+G25+H25+I25+J25) -> 0 | Q25: =P25/$P$42 -> 0
B26: RESTITUIÇÕES DIVERSAS | C26: 60957.54 | D26: 8152.86 | F26: 11812.38 | G26: 9724.98 | I26: 22426.9 | J26: 4711500.8 | P26: =SUM(C26+D26+E26+F26+G26+H26+I26+J26) -> 4824575.5
B27: OUTRAS RESTITUICOES | C27: 0 | P27: =SUM(C27+D27+E27+F27+G27+H27+I27+J27) -> 0
B28: 62955- ALUGUÉIS ( ALUGUEIS) | C28: 910.91 | D28: 910.91 | E28: 910.91 | F28: 910.91 | G28: 910.91 | H28: 910.91 | I28: 910.91 | J28: 910.91 | K28: 1138.63 | P28: =SUM(C28+D28+E28+F28+G28+H28+I28+J28) -> 7287.28 | Q28: =P28/$P$42 -> 1.9918247e-05
B29: 62962- OUTRAS RECEITAS EVENTUAIS | C29: 30209.08 | D29: 33948.25 | E29: 65068.1 | F29: 59063.2 | G29: 50816.07 | H29: 48527.17 | I29: 81464.03 | J29: 93817.3 | K29: 126548.4 | P29: =SUM(C29+D29+E29+F29+G29+H29+I29+J29) -> 462913.2 | Q29: =P29/$P$42 -> 0.0012652759
B30: 62974- MULTAS CONTRATUAIS | H30: 1 | I30: 366.66 | J30: 5430 | K30: 5430 | P30: =SUM(C30+D30+E30+F30+G30+H30+I30+J30) -> 5797.66 | Q30: =P30/$P$42 -> 1.5846684e-05
B31: 62961- MULTAS DECORRENTES DE SETENÇAS JUDICIAIS | C31: 13558.56 | D31: 16355.54 | E31: 17864.06 | F31: 17086.41 | G31: 5099.55 | H31: 26393.58 | I31: 16645.74 | J31: 9292.11 | K31: 9491.4 | P31: =SUM(C31+D31+E31+F31+G31+H31+I31+J31) -> 122295.55 | Q31: =P31/$P$42 -> 0.00033426917
B32: =SUM(B5:B31) -> 0 | C32: =SUM(C5:C31) -> 23385689 | D32: =SUM(D5:D31) -> 24433055 | E32: =SUM(E5:E31) -> 29088647 | F32: =SUM(F5:F31) -> 27219966 | G32: =SUM(G5:G31) -> 30481094 | H32: =SUM(H5:H31) -> 37013620 | I32: =SUM(I5:I31) -> 31083473 | ... Q32: =SUM(Q5:Q31) -> 0.63532803
M33: =SUM(M5:M31) -> 0 | P33: =SUM(C33+D33+E33+F33+G33+H33+I33+J33+L33+M33+N33+O33) -> 0
A34: RENDIMENTOS | B34: RENDIMENTOS FONTE 29 ( REMUNERACAO DE DEPOSITOS BANCARIOS – SELOS DE AUTENTICIDADE) | C34: 352065.78 | D34: 309831.91 | E34: 383934.24 | F34: 359436.47 | G34: 365598.99 | H34: 396552.64 | I34: 425969.96 | K34: 440000 | P34: =SUM(C34+D34+E34+F34+G34+H34+I34+J34+L34+M34+N34+O34) -> 2593390 | Q34: =P34/$P$42 -> 0.0070884862
B35: RENDIMENTOS FONTE 70 (JUROS E TITULOS DE RENDA) | C35: 5262950 | D35: 4513143.8 | E35: 5426144.9 | F35: 4701969 | G35: 4757746.1 | H35: 5009119.2 | I35: 5583187.6 | K35: 5700000 | P35: =SUM(C35+D35+E35+F35+G35+H35+I35+J35+L35+M35+N35+O35) -> 35254261 | Q35: =P35/$P$42 -> 0.096360108
B36: SPREAD DEPÓSITOS JUDICIAIS ( SPREAD SOBRE RENDIMENTOS DE DEPOSITOS JUDICIAIS) | C36: 9821108.3 | D36: 9992069 | E36: 10218785 | F36: 10544057 | G36: 10857943 | H36: 11075009 | I36: 11308744 | J36: 11388931 | K36: 11388931 | P36: =SUM(C36+D36+E36+F36+G36+H36+I36+J36+L36+M36+N36+O36) -> 85206646 | Q36: =P36/$P$42 -> 0.23289445
B37: SPREAD PRECATÓRIOS ( SPREAD SOBRE RENDIMENTOS DE PRECATORIOS JUDICIAIS) | P37: =SUM(C37+D37+E37+F37+G37+H37+I37+J37+L37+M37+N37+O37) -> 0 | Q37: =P37/$P$42 -> 0
B38: SPREAD FIANÇAS ( SPREAD SOBRE RENDIMENTOS DE FIANCAS CRIMINAIS) | D38: 1752093.8 | G38: 2303650.6 | H38: 697494.55 | I38: 786593.01 | P38: =SUM(C38+D38+E38+F38+G38+H38+I38+J38+L38+M38+N38+O38) -> 5539832 | Q38: =P38/$P$42 -> 0.015141966
B39: TOTAL RENDIMENTOS | C39: =SUM(C34:C38) -> 15436124 | D39: =SUM(D34:D38) -> 16567139 | E39: =SUM(E34:E38) -> 16028864 | F39: =SUM(F34:F38) -> 15605462 | G39: =SUM(G34:G38) -> 18284939 | H39: =SUM(H34:H38) -> 17178175 | I39: =SUM(I34:I38) -> 18104495 | J39: =SUM(J34:J38) -> 11388931 | ... Q39: =SUM(Q34:Q38) -> 0.35148501
P40: =SUM(C40+D40+E40+F40+G40+H40+I40+J40+L40+M40+N40+O40) -> 0
B41: CONSOLIDADO: DAEs + RENDIMENTOS (VALORES EM R$) | P41: =SUM(C41+D41+E41+F41+G41+H41+I41+J41+L41+M41+N41+O41) -> 0
...

Sheet CONSOLIDACAO MENSAL FUNSEG
B2: ARRECADAÇÃO MENSAL POR PRODUTO DE RECEITA
B3: ARRECADAÇÃO FUNSEG 040301 – EXERCÍCIO 2026
C4: JANEIRO | D4: FEVEREIRO | E4: MARÇO | F4: ABRIL | G4: MAIO | H4: JUNHO | I4: JULHO | J4: AGOSTO | K4: SETEMBRO | L4: OUTUBRO | M4: NOVEMBRO | N4: DEZEMBRO | O4: TOTAL | P4: % ACUMULADO / RECEITA TOTAL
B5: DAEs (VALORES EM R$)
A6: DAES | B6: 65020- CUSTAS PROCESSUAIS | C6: 375173.51 | D6: 435834.26 | E6: 532197.33 | F6: 532688.55 | G6: 548011.89 | H6: 597497.48 | I6: 613201.87 | J6: 554590.32 | O6: =SUM(C6+D6+E6+F6+G6+H6+I6+J6+K6+L6+M6+N6) -> 4189195.2 | P6: =O6/'CONSOLIDAÇÃO MENSAL FERMOJU 202'!$P$42 -> 0.011450284
B7: 65021- CUSTAS JUDICIAIS RECUPERADAS | C7: 3.78 | D7: 17.26 | E7: 493.76 | F7: 397.38 | G7: 1120.66 | H7: 554.32 | I7: 98.35 | O7: =SUM(C7+D7+E7+F7+G7+H7+I7+J7+K7+L7+M7+N7) -> 2685.51 | P7: =O7/'CONSOLIDAÇÃO MENSAL FERMOJU 202'!$P$42 -> 7.3402769e-06
B8: 65022- RECEITA DA DIVIDA ATIVA DE CUSTOS JUDICIAIS | C8: 3253.57 | D8: 2258.36 | E8: 12186.4 | F8: 2876.31 | G8: 3019.1 | H8: 4191.53 | I8: 3960.94 | J8: 2760.17 | O8: =SUM(C8+D8+E8+F8+G8+H8+I8+J8+K8+L8+M8+N8) -> 34506.38 | P8: =O8/'CONSOLIDAÇÃO MENSAL FERMOJU 202'!$P$42 -> 9.4315934e-05
B9: - OUTROS EMOLUMENTOS E CUSTAS EXTRA JUDICIAIS | O9: =SUM(C9+D9+E9+F9+G9+H9+I9+J9+K9+L9+M9+N9) -> 0 | P9: =O9/'CONSOLIDAÇÃO MENSAL FERMOJU 202'!$P$42 -> 0
B10: - VENDA DE SELOS DE AUTENTICIDADE | O10: =SUM(C10+D10+E10+F10+G10+H10+I10+J10+K10+L10+M10+N10) -> 0 | P10: =O10/'CONSOLIDAÇÃO MENSAL FERMOJU 202'!$P$42 -> 0
B11: - DEBITOS DE CORREIÇÃO | O11: =SUM(C11+D11+E11+F11+G11+H11+I11+J11+K11+L11+M11+N11) -> 0 | P11: =O11/'CONSOLIDAÇÃO MENSAL FERMOJU 202'!$P$42 -> 0
B12: - TARIFA DE INSCRIÇÃO EM CONCURSOS | O12: =SUM(C12+D12+E12+F12+G12+H12+I12+J12+K12+L12+M12+N12) -> 0 | P12: =O12/'CONSOLIDAÇÃO MENSAL FERMOJU 202'!$P$42 -> 0
B13: - RECEITA SOBRE A VENDA DE LIVROS | O13: =SUM(C13+D13+E13+F13+G13+H13+I13+J13+K13+L13+M13+N13) -> 0 | P13: =O13/'CONSOLIDAÇÃO MENSAL FERMOJU 202'!$P$42 -> 0
B14: - ESMEC | O14: =SUM(C14+D14+E14+F14+G14+H14+I14+J14+K14+L14+M14+N14) -> 0 | P14: =O14/'CONSOLIDAÇÃO MENSAL FERMOJU 202'!$P$42 -> 0
B15: - SERVIÇOS DE COMUNICAÇÃO | O15: =SUM(C15+D15+E15+F15+G15+H15+I15+J15+K15+L15+M15+N15) -> 0 | P15: =O15/'CONSOLIDAÇÃO MENSAL FERMOJU 202'!$P$42 -> 0
B16: - VENDA DE DIARIO | O16: =SUM(C16+D16+E16+F16+G16+H16+I16+J16+K16+L16+M16+N16) -> 0 | P16: =O16/'CONSOLIDAÇÃO MENSAL FERMOJU 202'!$P$42 -> 0
B17: - SERVICOS ADMINISTRATIVOS E COMERCIAIS GERAIS-CRECHE | O17: =SUM(C17+D17+E17+F17+G17+H17+I17+J17+K17+L17+M17+N17) -> 0 | P17: =O17/'CONSOLIDAÇÃO MENSAL FERMOJU 202'!$P$42 -> 0
B18: - DISTRIBUIÇÃO DE TÍTULOS PARA PROTESTO | O18: =SUM(C18+D18+E18+F18+G18+H18+I18+J18+K18+L18+M18+N18) -> 0 | P18: =O18/'CONSOLIDAÇÃO MENSAL FERMOJU 202'!$P$42 -> 0
B19: - SERVICOS ADMINISTRATIVOS E COMERCIAIS GERAIS – SELOS PAC | O19: =SUM(C19+D19+E19+F19+G19+H19+I19+J19+K19+L19+M19+N19) -> 0 | P19: =O19/'CONSOLIDAÇÃO MENSAL FERMOJU 202'!$P$42 -> 0
B20: ALIENAÇÃO DE IMÓVEIS RURAIS | O20: =SUM(C20+D20+E20+F20+G20+H20+I20+J20+K20+L20+M20+N20) -> 0 | P20: =O20/'CONSOLIDAÇÃO MENSAL FERMOJU 202'!$P$42 -> 0
... B25: - RESTITUIÇÕES DIVERSAS | O25: =SUM(C25+D25+E25+F25+G25+H25+I25+J25+K25+L25+M25+N25) -> 0 | P25: =O25/'CONSOLIDAÇÃO MENSAL FERMOJU 202'!$P$42 -> 0
B26: 65019- ALUGUÉIS ( ALUGUEIS) | C26: 227.72 | D26: 227.72 | E26: 227.72 | F26: 227.72 | G26: 227.72 | H26: 227.72 | I26: 227.72 | J26: 227.72 | O26: =SUM(C26+D26+E26+F26+G26+H26+I26+J26+K26+L26+M26+N26) -> 1821.76 | P26: =O26/'CONSOLIDAÇÃO MENSAL FERMOJU 202'!$P$42 -> 4.9793979e-06
B27: - OUTRAS RECEITAS EVENTUAIS | O27: =SUM(C27+D27+E27+F27+G27+H27+I27+J27+K27+L27+M27+N27) -> 0 | P27: =O27/'CONSOLIDAÇÃO MENSAL FERMOJU 202'!$P$42 -> 0
B28: - MULTAS CONTRATUAIS | O28: =SUM(C28+D28+E28+F28+G28+H28+I28+J28+K28+L28+M28+N28) -> 0 | P28: =O28/'CONSOLIDAÇÃO MENSAL FERMOJU 202'!$P$42 -> 0
B29: - MULTAS DECORRENTES DE SETENÇAS JUDICIAIS | O29: =SUM(C29+D29+E29+F29+G29+H29+I29+J29+K29+L29+M29+N29) -> 0 | P29: =O29/'CONSOLIDAÇÃO MENSAL FERMOJU 202'!$P$42 -> 0
C30: =SUM(C6:C29) -> 378658.58 | D30: =SUM(D6:D29) -> 438337.6 | E30: =SUM(E6:E29) -> 545105.21 | F30: =SUM(F6:F29) -> 536189.96 | G30: =SUM(G6:G29) -> 552379.37 | H30: =SUM(H6:H29) -> 602471.05 | I30: =SUM(I6:I29) -> 617488.88 | J30: =SUM(J6:J29) -> 557578.21 | ... N30: =SUM(N6:N29) -> 0 | O30: =SUM(C30+D30+E30+F30+G30+H30+I30+J30+K30+L30+M30+N30) -> 4228208.9
O31: =SUM(C31+D31+E31+F31+G31+H31+I31+J31+K31+L31+M31+N31) -> 0
A32: RENDIMENTOS | B32: RENDIMENTOS FONTE 29 ( REMUNERACAO DE DEPOSITOS BANCARIOS – SELOS DE AUTENTICIDADE) | O32: =SUM(C32+D32+E32+F32+G32+H32+I32+J32+K32+L32+M32+N32) -> 0 | P32: =O32/'CONSOLIDAÇÃO MENSAL FERMOJU 202'!$P$42 -> 0
B33: RENDIMENTOS FONTE 70 (JUROS E TITULOS DE RENDA) | C33: 378835.11 | D33: 327536.71 | E33: 398236.76 | F33: 357242.19 | G33: 353858.95 | H33: 370975 | I33: 403533.51 | O33: =SUM(C33+D33+E33+F33+G33+H33+I33+J33+K33+L33+M33+N33) -> 2590218.2 | P33: =O33/'CONSOLIDAÇÃO MENSAL FERMOJU 202'!$P$42 -> 0.0070798168
B34: SPREAD DEPÓSITOS JUDICIAIS ( SPREAD SOBRE RENDIMENTOS DE DEPOSITOS JUDICIAIS) | O34: =SUM(C34+D34+E34+F34+G34+H34+I34+J34+K34+L34+M34+N34) -> 0 | P34: =O34/'CONSOLIDAÇÃO MENSAL FERMOJU 202'!$P$42 -> 0
B35: SPREAD PRECATÓRIOS ( SPREAD SOBRE RENDIMENTOS DE PRECATORIOS JUDICIAIS) | O35: =SUM(C35+D35+E35+F35+G35+H35+I35+J35+K35+L35+M35+N35) -> 0
B36: SPREAD FIANÇAS ( SPREAD SOBRE RENDIMENTOS DE FIANCAS CRIMINAIS) | O36: =SUM(C36+D36+E36+F36+G36+H36+I36+J36+K36+L36+M36+N36) -> 0 | P36: =O36/'CONSOLIDAÇÃO MENSAL FERMOJU 202'!$P$42 -> 0
B37: JUROS SOBRE O CAPITAL PROPRIO | O37: =SUM(C37+D37+E37+F37+G37+H37+I37+J37+K37+L37+M37+N37) -> 0
B38: TOTAL RENDIMENTOS | C38: =SUM(C32:C36) -> 378835.11 | D38: =SUM(D32:D37) -> 327536.71 | E38: =SUM(E32:E36) -> 398236.76 | F38: =SUM(F32:F36) -> 357242.19 | G38: =SUM(G32:G36) -> 353858.95 | H38: =SUM(H32:H36) -> 370975 | I38: =SUM(I32:I36) -> 403533.51 | J38: =SUM(J32:J36) -> 0 | K38: =SUM(K32:K36) -> 0 | L38: =SUM(L32:L36) -> 0 | ... N38: =SUM(N32:N36) -> 0 | O38: =SUM(C38+D38+E38+F38+G38+H38+I38+J38+K38+L38+M38+N38) -> 2590218.2 | P38: =SUM(P32:P36) -> 0.0070798168
B40: CONSOLIDADO: DAEs + RENDIMENTOS (VALORES EM R$) | O40: =SUM(C40+D40+E40+F40+G40+H40+I40+J40+K40+L40+M40+N40) -> 0
B41: TOTAL CONSOLIDADO | C41: =C30+C38 -> 757493.69 | D41: =D30+D38 -> 765874.31 | E41: =E30+E38 -> 943341.97 | F41: =F30+F38 -> 893432.15 | G41: =G30+G38 -> 906238.32 | H41: =H30+H38 -> 973446.05 | I41: =I30+I38 -> 1021022.4 | J41: =J30+J38 -> 557578.21 | ... N41: =N30+N38 -> 0 | O41: =SUM(C41+D41+E41+F41+G41+H41+I41+J41+K41+L41+M41+N41) -> 6818427.1 | P41: =P30+P38 -> 0.0070798168

Sheet CONSOLIDACAO MENSAL FECDOJ
B2: ARRECADAÇÃO MENSAL POR PRODUTO DE RECEITA
B3: ARRECADAÇÃO FECDOJ 040401 – EXERCÍCIO 2026
C4: JANEIRO | D4: FEVEREIRO | E4: MARÇO | F4: ABRIL | G4: MAIO | H4: JUNHO | I4: JULHO | J4: AGOSTO | K4: SETEMBRO | L4: OUTUBRO | M4: NOVEMBRO | N4: DEZEMBRO | O4: TOTAL | P4: % ACUMULADO / RECEITA TOTAL
B5: DAEs (VALORES EM R$)
A6: DAES | B6: 62966- CUSTAS PROCESSUAIS | C6: 334422.25 | D6: 368398.31 | E6: 436896.07 | F6: 417860.33 | G6: 472151.16 | H6: 497436.51 | I6: 525433.9 | J6: 471772.48 | O6: =SUM(C6+D6+E6+F6+G6+H6+I6+J6+K6+L6+M6+N6) -> 3524371 | P6: =O6/'CONSOLIDAÇÃO MENSAL FERMOJU 202'!$P$42 -> 0.009633127
B7: CUSTAS JUDICIAIS RECUPERADAS | O7: =SUM(C7+D7+E7+F7+G7+H7+I7+J7+K7+L7+M7+N7) -> 0 | P7: =O7/'CONSOLIDAÇÃO MENSAL FERMOJU 202'!$P$42 -> 0
B8: RECEITA DA DIVIDA ATIVA DE CUSTOS JUDICIAIS | O8: =SUM(C8+D8+E8+F8+G8+H8+I8+J8+K8+L8+M8+N8) -> 0 | P8: =O8/'CONSOLIDAÇÃO MENSAL FERMOJU 202'!$P$42 -> 0
B9: OUTROS EMOLUMENTOS E CUSTAS EXTRA JUDICIAIS | O9: =SUM(C9+D9+E9+F9+G9+H9+I9+J9+K9+L9+M9+N9) -> 0 | P9: =O9/'CONSOLIDAÇÃO MENSAL FERMOJU 202'!$P$42 -> 0
B10: VENDA DE SELOS DE AUTENTICIDADE | O10: =SUM(C10+D10+E10+F10+G10+H10+I10+J10+K10+L10+M10+N10) -> 0 | P10: =O10/'CONSOLIDAÇÃO MENSAL FERMOJU 202'!$P$42 -> 0
B11: DEBITOS DE CORREIÇÃO | O11: =SUM(C11+D11+E11+F11+G11+H11+I11+J11+K11+L11+M11+N11) -> 0 | P11: =O11/'CONSOLIDAÇÃO MENSAL FERMOJU 202'!$P$42 -> 0
B12: TARIFA DE INSCRIÇÃO EM CONCURSOS | O12: =SUM(C12+D12+E12+F12+G12+H12+I12+J12+K12+L12+M12+N12) -> 0 | P12: =O12/'CONSOLIDAÇÃO MENSAL FERMOJU 202'!$P$42 -> 0
B13: RECEITA SOBRE A VENDA DE LIVROS | O13: =SUM(C13+D13+E13+F13+G13+H13+I13+J13+K13+L13+M13+N13) -> 0 | P13: =O13/'CONSOLIDAÇÃO MENSAL FERMOJU 202'!$P$42 -> 0
B14: SERVIÇOS DE COMUNICAÇÃO | O14: =SUM(C14+D14+E14+F14+G14+H14+I14+J14+K14+L14+M14+N14) -> 0 | P14: =O14/'CONSOLIDAÇÃO MENSAL FERMOJU 202'!$P$42 -> 0
B15: VENDA DE DIARIO | O15: =SUM(C15+D15+E15+F15+G15+H15+I15+J15+K15+L15+M15+N15) -> 0 | P15: =O15/'CONSOLIDAÇÃO MENSAL FERMOJU 202'!$P$42 -> 0
B16: SERVICOS ADMINISTRATIVOS E COMERCIAIS GERAIS-CRECHE | O16: =SUM(C16+D16+E16+F16+G16+H16+I16+J16+K16+L16+M16+N16) -> 0 | P16: =O16/'CONSOLIDAÇÃO MENSAL FERMOJU 202'!$P$42 -> 0
B17: DISTRIBUIÇÃO DE TÍTULOS PARA PROTESTO | O17: =SUM(C17+D17+E17+F17+G17+H17+I17+J17+K17+L17+M17+N17) -> 0 | P17: =O17/'CONSOLIDAÇÃO MENSAL FERMOJU 202'!$P$42 -> 0
B18: SERVICOS ADMINISTRATIVOS E COMERCIAIS GERAIS – SELOS PAC | O18: =SUM(C18+D18+E18+F18+G18+H18+I18+J18+K18+L18+M18+N18) -> 0 | P18: =O18/'CONSOLIDAÇÃO MENSAL FERMOJU 202'!$P$42 -> 0
... B26: ALUGUÉIS ( ALUGUEIS) | O26: =SUM(C26+D26+E26+F26+G26+H26+I26+J26+K26+L26+M26+N26) -> 0 | P26: =O26/'CONSOLIDAÇÃO MENSAL FERMOJU 202'!$P$42 -> 0
B27: OUTRAS RECEITAS EVENTUAIS | G27: ='1__POR_RECEITA_DETALHADA'!K134 -> 0 | O27: =SUM(C27+D27+E27+F27+G27+H27+I27+J27+K27+L27+M27+N27) -> 0 | P27: =O27/'CONSOLIDAÇÃO MENSAL FERMOJU 202'!$P$42 -> 0
B28: MULTAS CONTRATUAIS | O28: =SUM(C28+D28+E28+F28+G28+H28+I28+J28+K28+L28+M28+N28) -> 0 | P28: =O28/'CONSOLIDAÇÃO MENSAL FERMOJU 202'!$P$42 -> 0
B29: MULTAS DECORRENTES DE SETENÇAS JUDICIAIS | G29: ='1__POR_RECEITA_DETALHADA'!G78 -> 0 | O29: =SUM(C29+D29+E29+F29+G29+H29+I29+J29+K29+L29+M29+N29) -> 0 | P29: =O29/'CONSOLIDAÇÃO MENSAL FERMOJU 202'!$P$42 -> 0
B30: =SUM(B6:B29) -> 0 | C30: =SUM(C6:C29) -> 334422.25 | D30: =SUM(D6:D29) -> 368398.31 | E30: =SUM(E6:E29) -> 436896.07 | F30: =SUM(F6:F29) -> 417860.33 | G30: =SUM(G6:G29) -> 472151.16 | H30: =SUM(H6:H29) -> 497436.51 | I30: =SUM(I6:I29) -> 525433.9 | ... N30: =SUM(N6:N29) -> 0 | O30: =SUM(C30+D30+E30+F30+G30+H30+I30+J30+K30+L30+M30+N30) -> 3524371 | P30: =O30/'CONSOLIDAÇÃO MENSAL FERMOJU 202'!$P$42 -> 0.009633127
O31: =SUM(C31+D31+E31+F31+G31+H31+I31+J31+K31+L31+M31+N31) -> 0 | P31: =O31/'CONSOLIDAÇÃO MENSAL FERMOJU 202'!$P$42 -> 0
A32: RENDIMENTOS | B32: RENDIMENTOS FONTE 29 ( REMUNERACAO DE DEPOSITOS BANCARIOS – SELOS DE AUTENTICIDADE) | O32: =SUM(C32+D32+E32+F32+G32+H32+I32+J32+K32+L32+M32+N32) -> 0 | P32: =O32/'CONSOLIDAÇÃO MENSAL FERMOJU 202'!$P$42 -> 0
B33: RENDIMENTOS FONTE 70 (JUROS E TITULOS DE RENDA) | C33: 31936.93 | D33: 29114.06 | E33: 35179.86 | F33: 32471.62 | G33: 32410.5 | H33: 33299.86 | I33: 37420.55 | O33: =SUM(C33+D33+E33+F33+G33+H33+I33+J33+K33+L33+M33+N33) -> 231833.38 | P33: =O33/'CONSOLIDAÇÃO MENSAL FERMOJU 202'!$P$42 -> 0.00063366779
B34: SPREAD DEPÓSITOS JUDICIAIS ( SPREAD SOBRE RENDIMENTOS DE DEPOSITOS JUDICIAIS) | O34: =SUM(C34+D34+E34+F34+G34+H34+I34+J34+K34+L34+M34+N34) -> 0 | P34: =O34/'CONSOLIDAÇÃO MENSAL FERMOJU 202'!$P$42 -> 0
B35: SPREAD PRECATÓRIOS ( SPREAD SOBRE RENDIMENTOS DE PRECATORIOS JUDICIAIS) | O35: =SUM(C35+D35+E35+F35+G35+H35+I35+J35+K35+L35+M35+N35) -> 0 | P35: =O35/'CONSOLIDAÇÃO MENSAL FERMOJU 202'!$P$42 -> 0
B36: SPREAD FIANÇAS ( SPREAD SOBRE RENDIMENTOS DE FIANCAS CRIMINAIS) | O36: =SUM(C36+D36+E36+F36+G36+H36+I36+J36+K36+L36+M36+N36) -> 0 | P36: =O36/'CONSOLIDAÇÃO MENSAL FERMOJU 202'!$P$42 -> 0
B37: TOTAL RENDIMENTOS | C37: =SUM(C32:C36) -> 31936.93 | D37: =SUM(D32:D36) -> 29114.06 | E37: =SUM(E32:E36) -> 35179.86 | F37: =SUM(F32:F36) -> 32471.62 | G37: =SUM(G32:G36) -> 32410.5 | H37: =SUM(H32:H36) -> 33299.86 | I37: =SUM(I32:I36) -> 37420.55 | J37: =SUM(J32:J36) -> 0 | ... N37: =SUM(N32:N36) -> 0 | O37: =SUM(C37+D37+E37+F37+G37+H37+I37+J37+K37+L37+M37+N37) -> 231833.38 | P37: =O37/'CONSOLIDAÇÃO MENSAL FERMOJU 202'!$P$42 -> 0.00063366779
O38: =SUM(C38+D38+E38+F38+G38+H38+I38+J38+K38+L38+M38+N38) -> 0 | P38: =O38/'CONSOLIDAÇÃO MENSAL FERMOJU 202'!$P$42 -> 0
B39: CONSOLIDADO: DAEs + RENDIMENTOS (VALORES EM R$) | O39: =SUM(C39+D39+E39+F39+G39+H39+I39+J39+K39+L39+M39+N39) -> 0 | P39: =O39/'CONSOLIDAÇÃO MENSAL FERMOJU 202'!$P$42 -> 0
B40: TOTAL CONSOLIDADO | C40: =C30+C37 -> 366359.18 | D40: =D30+D37 -> 397512.37 | E40: =E30+E37 -> 472075.93 | F40: =F30+F37 -> 450331.95 | G40: =G30+G37 -> 504561.66 | H40: =H30+H37 -> 530736.37 | I40: =I30+I37 -> 562854.45 | J40: =J30+J37 -> 471772.48 | ... N40: =N30+N37 -> 0 | O40: =SUM(C40+D40+E40+F40+G40+H40+I40+J40+K40+L40+M40+N40) -> 3756204.4 | P40: =O40/'CONSOLIDAÇÃO MENSAL FERMOJU 202'!$P$42 -> 0.010266795

Sheet Consolidado
D1: 46023 | E1: 46054 | F1: 46082 | G1: 46113 | H1: 46143 | I1: 46174 | J1: 46204 | K1: 46235 | L1: 46266 | M1: 46296 | N1: 46327 | O1: 46357
A2: Fermoju | B2: Judicial | C2: 62950- CUSTAS PROCESSUAIS | D2: ='CONSOLIDAÇÃO MENSAL FERMOJU 202'!C5 -> 12132542 | E2: ='CONSOLIDAÇÃO MENSAL FERMOJU 202'!D5 -> 14095018 | F2: ='CONSOLIDAÇÃO MENSAL FERMOJU 202'!E5 -> 17211344 | G2: ='CONSOLIDAÇÃO MENSAL FERMOJU 202'!F5 -> 17227005 | H2: ='CONSOLIDAÇÃO MENSAL FERMOJU 202'!G5 -> 17722596 | I2: ='CONSOLIDAÇÃO MENSAL FERMOJU 202'!H5 -> 19322804 | J2: ='CONSOLIDAÇÃO MENSAL FERMOJU 202'!I5 -> 19765793 | K2: ='CONSOLIDAÇÃO MENSAL FERMOJU 202'!J5 -> 17989998 | L2: ='CONSOLIDAÇÃO MENSAL FERMOJU 202'!L5 -> 0 | M2: ='CONSOLIDAÇÃO MENSAL FERMOJU 202'!M5 -> 0 | N2: ='CONSOLIDAÇÃO MENSAL FERMOJU 202'!N5 -> 0 | O2: ='CONSOLIDAÇÃO MENSAL FERMOJU 202'!O5 -> 0
A3: Fermoju | B3: Judicial | C3: 62975- CUSTAS JUDICIAIS RECUPERADAS | D3: ='CONSOLIDAÇÃO MENSAL FERMOJU 202'!C6 -> 123.44 | E3: ='CONSOLIDAÇÃO MENSAL FERMOJU 202'!D6 -> 559.06 | F3: ='CONSOLIDAÇÃO MENSAL FERMOJU 202'!E6 -> 15966.32 | G3: ='CONSOLIDAÇÃO MENSAL FERMOJU 202'!F6 -> 12850.2 | H3: ='CONSOLIDAÇÃO MENSAL FERMOJU 202'!G6 -> 36240.74 | I3: ='CONSOLIDAÇÃO MENSAL FERMOJU 202'!H6 -> 17925.72 | J3: ='CONSOLIDAÇÃO MENSAL FERMOJU 202'!I6 -> 3181.1 | K3: ='CONSOLIDAÇÃO MENSAL FERMOJU 202'!J6 -> 9931.26 | L3: ='CONSOLIDAÇÃO MENSAL FERMOJU 202'!L6 -> 0 | M3: ='CONSOLIDAÇÃO MENSAL FERMOJU 202'!M6 -> 0 | N3: ='CONSOLIDAÇÃO MENSAL FERMOJU 202'!N6 -> 0 | O3: ='CONSOLIDAÇÃO MENSAL FERMOJU 202'!O6 -> 0 | R3: Judicial | S3: Extra Judicial | T3: Rendimento
A4: Fermoju | B4: Judicial | C4: 63531- RECEITA DA DIVIDA ATIVA DE CUSTOS JUDICIAIS | D4: ='CONSOLIDAÇÃO MENSAL FERMOJU 202'!C7 -> 121669.9 | E4: ='CONSOLIDAÇÃO MENSAL FERMOJU 202'!D7 -> 84458.06 | F4: ='CONSOLIDAÇÃO MENSAL FERMOJU 202'!E7 -> 455638.39 | G4: ='CONSOLIDAÇÃO MENSAL FERMOJU 202'!F7 -> 107559.12 | H4: ='CONSOLIDAÇÃO MENSAL FERMOJU 202'!G7 -> 112897.31 | I4: ='CONSOLIDAÇÃO MENSAL FERMOJU 202'!H7 -> 156731.15 | J4: ='CONSOLIDAÇÃO MENSAL FERMOJU 202'!I7 -> 146816.23 | K4: ='CONSOLIDAÇÃO MENSAL FERMOJU 202'!J7 -> 104509.19 | L4: ='CONSOLIDAÇÃO MENSAL FERMOJU 202'!L7 -> 0 | M4: ='CONSOLIDAÇÃO MENSAL FERMOJU 202'!M7 -> 0 | N4: ='CONSOLIDAÇÃO MENSAL FERMOJU 202'!N7 -> 0 | O4: ='CONSOLIDAÇÃO MENSAL FERMOJU 202'!O7 -> 0 | Q4: 46023 | R4: =SUMIF($B:$B,R3,D:D) -> 12967188 | S4: =SUMIF($B:$B,S3,D:D) -> 7166784.7 | T4: =SUMIF($B:$B,T3,D:D) -> 15846896
A5: Fermoju | B5: Extra Judicial | C5: 62948- OUTROS EMOLUMENTOS E CUSTAS EXTRA JUDICIAIS | D5: ='CONSOLIDAÇÃO MENSAL FERMOJU 202'!C8 -> 3825622 | E5: ='CONSOLIDAÇÃO MENSAL FERMOJU 202'!D8 -> 3689474.8 | F5: ='CONSOLIDAÇÃO MENSAL FERMOJU 202'!E8 -> 4767496.8 | G5: ='CONSOLIDAÇÃO MENSAL FERMOJU 202'!F8 -> 3803868.1 | H5: ='CONSOLIDAÇÃO MENSAL FERMOJU 202'!G8 -> 4440325.9 | I5: ='CONSOLIDAÇÃO MENSAL FERMOJU 202'!H8 -> 4999301.1 | J5: ='CONSOLIDAÇÃO MENSAL FERMOJU 202'!I8 -> 4464736.7 | K5: ='CONSOLIDAÇÃO MENSAL FERMOJU 202'!J8 -> 4496707.3 | L5: ='CONSOLIDAÇÃO MENSAL FERMOJU 202'!L8 -> 0 | M5: ='CONSOLIDAÇÃO MENSAL FERMOJU 202'!M8 -> 0 | N5: ='CONSOLIDAÇÃO MENSAL FERMOJU 202'!N8 -> 0 | O5: ='CONSOLIDAÇÃO MENSAL FERMOJU 202'!O8 -> 0 | Q5: 46054 | R5: =SUMIF($B:$B,$R$3,E:E) -> 14986544 | S5: =SUMIF($B:$B,$R$3,E:E) -> 14986544 | T5: =SUMIF($B:$B,$R$3,E:E) -> 14986544
A6: Fermoju | B6: Extra Judicial | C6: 62947- VENDA DE SELOS DE AUTENTICIDADE | D6: ='CONSOLIDAÇÃO MENSAL FERMOJU 202'!C9 -> 3341162.7 | E6: ='CONSOLIDAÇÃO MENSAL FERMOJU 202'!D9 -> 3135505 | F6: ='CONSOLIDAÇÃO MENSAL FERMOJU 202'!E9 -> 4178974.3 | G6: ='CONSOLIDAÇÃO MENSAL FERMOJU 202'!F9 -> 3172814.2 | H6: ='CONSOLIDAÇÃO MENSAL FERMOJU 202'!G9 -> 3899224.8 | I6: ='CONSOLIDAÇÃO MENSAL FERMOJU 202'!H9 -> 4312644.9 | J6: ='CONSOLIDAÇÃO MENSAL FERMOJU 202'!I9 -> 3879523.4 | K6: ='CONSOLIDAÇÃO MENSAL FERMOJU 202'!J9 -> 3896145.1 | L6: ='CONSOLIDAÇÃO MENSAL FERMOJU 202'!L9 -> 0 | M6: ='CONSOLIDAÇÃO MENSAL FERMOJU 202'!M9 -> 0 | N6: ='CONSOLIDAÇÃO MENSAL FERMOJU 202'!N9 -> 0 | O6: ='CONSOLIDAÇÃO MENSAL FERMOJU 202'!O9 -> 0 | Q6: 46082 | R6: =SUMIF($B:$B,R3,F:F) -> 18664722 | S6: =SUMIF($B:$B,S3,F:F) -> 8946471.1 | T6: =SUMIF($B:$B,T3,F:F) -> 16462281
A7: Fermoju | B7: Rendimento | C7: RENDIMENTOS FONTE 29 ( REMUNERACAO DE DEPOSITOS BANCARIOS – SELOS DE AUTENTICIDADE) | D7: ='CONSOLIDAÇÃO MENSAL FERMOJU 202'!C34 -> 352065.78 | E7: ='CONSOLIDAÇÃO MENSAL FERMOJU 202'!D34 -> 309831.91 | F7: ='CONSOLIDAÇÃO MENSAL FERMOJU 202'!E34 -> 383934.24 | G7: ='CONSOLIDAÇÃO MENSAL FERMOJU 202'!F34 -> 359436.47 | H7: ='CONSOLIDAÇÃO MENSAL FERMOJU 202'!G34 -> 365598.99 | I7: ='CONSOLIDAÇÃO MENSAL FERMOJU 202'!H34 -> 396552.64 | J7: ='CONSOLIDAÇÃO MENSAL FERMOJU 202'!I34 -> 425969.96 | K7: ='CONSOLIDAÇÃO MENSAL FERMOJU 202'!J34 -> 0 | L7: ='CONSOLIDAÇÃO MENSAL FERMOJU 202'!L34 -> 0 | M7: ='CONSOLIDAÇÃO MENSAL FERMOJU 202'!M34 -> 0 | N7: ='CONSOLIDAÇÃO MENSAL FERMOJU 202'!N34 -> 0 | O7: ='CONSOLIDAÇÃO MENSAL FERMOJU 202'!O34 -> 0 | Q7: 46113 | R7: =SUMIF($B:$B,R3,G:G) -> 18301237 | S7: =SUMIF($B:$B,S3,G:G) -> 6976682.3 | T7: =SUMIF($B:$B,T3,G:G) -> 15995176
A8: Fermoju | B8: Rendimento | C8: RENDIMENTOS FONTE 70 (JUROS E TITULOS DE RENDA) | D8: ='CONSOLIDAÇÃO MENSAL FERMOJU 202'!C35 -> 5262950 | E8: ='CONSOLIDAÇÃO MENSAL FERMOJU 202'!D35 -> 4513143.8 | F8: ='CONSOLIDAÇÃO MENSAL FERMOJU 202'!E35 -> 5426144.9 | G8: ='CONSOLIDAÇÃO MENSAL FERMOJU 202'!F35 -> 4701969 | H8: ='CONSOLIDAÇÃO MENSAL FERMOJU 202'!G35 -> 4757746.1 | I8: ='CONSOLIDAÇÃO MENSAL FERMOJU 202'!H35 -> 5009119.2 | J8: ='CONSOLIDAÇÃO MENSAL FERMOJU 202'!I35 -> 5583187.6 | K8: ='CONSOLIDAÇÃO MENSAL FERMOJU 202'!J35 -> 0 | L8: ='CONSOLIDAÇÃO MENSAL FERMOJU 202'!L35 -> 0 | M8: ='CONSOLIDAÇÃO MENSAL FERMOJU 202'!M35 -> 0 | N8: ='CONSOLIDAÇÃO MENSAL FERMOJU 202'!N35 -> 0 | O8: ='CONSOLIDAÇÃO MENSAL FERMOJU 202'!O35 -> 0 | Q8: 46143 | R8: =SUMIF($B:$B,R3,H:H) -> 18896036 | S8: =SUMIF($B:$B,S3,H:H) -> 8339550.7 | T8: =SUMIF($B:$B,T3,H:H) -> 18671209
A9: Fermoju | B9: Rendimento | C9: SPREAD DEPÓSITOS JUDICIAIS ( SPREAD SOBRE RENDIMENTOS DE DEPOSITOS JUDICIAIS) | D9: ='CONSOLIDAÇÃO MENSAL FERMOJU 202'!C36 -> 9821108.3 | E9: ='CONSOLIDAÇÃO MENSAL FERMOJU 202'!D36 -> 9992069 | F9: ='CONSOLIDAÇÃO MENSAL FERMOJU 202'!E36 -> 10218785 | G9: ='CONSOLIDAÇÃO MENSAL FERMOJU 202'!F36 -> 10544057 | H9: ='CONSOLIDAÇÃO MENSAL FERMOJU 202'!G36 -> 10857943 | I9: ='CONSOLIDAÇÃO MENSAL FERMOJU 202'!H36 -> 11075009 | J9: ='CONSOLIDAÇÃO MENSAL FERMOJU 202'!I36 -> 11308744 | K9: ='CONSOLIDAÇÃO MENSAL FERMOJU 202'!J36 -> 11388931 | L9: ='CONSOLIDAÇÃO MENSAL FERMOJU 202'!L36 -> 0 | M9: ='CONSOLIDAÇÃO MENSAL FERMOJU 202'!M36 -> 0 | N9: ='CONSOLIDAÇÃO MENSAL FERMOJU 202'!N36 -> 0 | O9: ='CONSOLIDAÇÃO MENSAL FERMOJU 202'!O36 -> 0 | Q9: 46174 | R9: =SUMIF($B:$B,R3,I:I) -> 20597140 | S9: =SUMIF($B:$B,S3,I:I) -> 9311946 | T9: =SUMIF($B:$B,T3,I:I) -> 17582450
A10: Fermoju | B10: Rendimento | C10: SPREAD PRECATÓRIOS ( SPREAD SOBRE RENDIMENTOS DE PRECATORIOS JUDICIAIS) | D10: ='CONSOLIDAÇÃO MENSAL FERMOJU 202'!C37 -> 0 | E10: ='CONSOLIDAÇÃO MENSAL FERMOJU 202'!D37 -> 0 | F10: ='CONSOLIDAÇÃO MENSAL FERMOJU 202'!E37 -> 0 | G10: ='CONSOLIDAÇÃO MENSAL FERMOJU 202'!F37 -> 0 | H10: ='CONSOLIDAÇÃO MENSAL FERMOJU 202'!G37 -> 0 | I10: ='CONSOLIDAÇÃO MENSAL FERMOJU 202'!H37 -> 0 | J10: ='CONSOLIDAÇÃO MENSAL FERMOJU 202'!I37 -> 0 | K10: ='CONSOLIDAÇÃO MENSAL FERMOJU 202'!J37 -> 0 | L10: ='CONSOLIDAÇÃO MENSAL FERMOJU 202'!L37 -> 0 | M10: ='CONSOLIDAÇÃO MENSAL FERMOJU 202'!M37 -> 0 | N10: ='CONSOLIDAÇÃO MENSAL FERMOJU 202'!N37 -> 0 | O10: ='CONSOLIDAÇÃO MENSAL FERMOJU 202'!O37 -> 0
A11: Fermoju | B11: Rendimento | C11: SPREAD FIANÇAS ( SPREAD SOBRE RENDIMENTOS DE FIANCAS CRIMINAIS) | D11: ='CONSOLIDAÇÃO MENSAL FERMOJU 202'!C38 -> 0 | E11: ='CONSOLIDAÇÃO MENSAL FERMOJU 202'!D38 -> 1752093.8 | F11: ='CONSOLIDAÇÃO MENSAL FERMOJU 202'!E38 -> 0 | G11: ='CONSOLIDAÇÃO MENSAL FERMOJU 202'!F38 -> 0 | H11: ='CONSOLIDAÇÃO MENSAL FERMOJU 202'!G38 -> 2303650.6 | I11: ='CONSOLIDAÇÃO MENSAL FERMOJU 202'!H38 -> 697494.55 | J11: ='CONSOLIDAÇÃO MENSAL FERMOJU 202'!I38 -> 786593.01 | K11: ='CONSOLIDAÇÃO MENSAL FERMOJU 202'!J38 -> 0 | L11: ='CONSOLIDAÇÃO MENSAL FERMOJU 202'!L38 -> 0 | M11: ='CONSOLIDAÇÃO MENSAL FERMOJU 202'!M38 -> 0 | N11: ='CONSOLIDAÇÃO MENSAL FERMOJU 202'!N38 -> 0 | O11: ='CONSOLIDAÇÃO MENSAL FERMOJU 202'!O38 -> 0
A12: Funseg | B12: Judicial | C12: 65020- CUSTAS PROCESSUAIS | D12: ='CONSOLIDACAO MENSAL FUNSEG'!C6 -> 375173.51 | E12: ='CONSOLIDACAO MENSAL FUNSEG'!D6 -> 435834.26 | F12: ='CONSOLIDACAO MENSAL FUNSEG'!E6 -> 532197.33 | G12: ='CONSOLIDACAO MENSAL FUNSEG'!F6 -> 532688.55 | H12: ='CONSOLIDACAO MENSAL FUNSEG'!G6 -> 548011.89 | I12: ='CONSOLIDACAO MENSAL FUNSEG'!H6 -> 597497.48 | J12: ='CONSOLIDACAO MENSAL FUNSEG'!I6 -> 613201.87 | K12: ='CONSOLIDACAO MENSAL FUNSEG'!J6 -> 554590.32 | ... O12: ='CONSOLIDACAO MENSAL FUNSEG'!N6 -> 0
A13: Funseg | B13: Judicial | C13: 65021- CUSTAS JUDICIAIS RECUPERADAS | D13: ='CONSOLIDACAO MENSAL FUNSEG'!C7 -> 3.78 | E13: ='CONSOLIDACAO MENSAL FUNSEG'!D7 -> 17.26 | F13: ='CONSOLIDACAO MENSAL FUNSEG'!E7 -> 493.76 | G13: ='CONSOLIDACAO MENSAL FUNSEG'!F7 -> 397.38 | H13: ='CONSOLIDACAO MENSAL FUNSEG'!G7 -> 1120.66 | I13: ='CONSOLIDACAO MENSAL FUNSEG'!H7 -> 554.32 | J13: ='CONSOLIDACAO MENSAL FUNSEG'!I7 -> 98.35 | K13: ='CONSOLIDACAO MENSAL FUNSEG'!J7 -> 0 | ... O13: ='CONSOLIDACAO MENSAL FUNSEG'!N7 -> 0
A14: Funseg | B14: Judicial | C14: 65022- RECEITA DA DIVIDA ATIVA DE CUSTOS JUDICIAIS | D14: ='CONSOLIDACAO MENSAL FUNSEG'!C8 -> 3253.57 | E14: ='CONSOLIDACAO MENSAL FUNSEG'!D8 -> 2258.36 | F14: ='CONSOLIDACAO MENSAL FUNSEG'!E8 -> 12186.4 | G14: ='CONSOLIDACAO MENSAL FUNSEG'!F8 -> 2876.31 | H14: ='CONSOLIDACAO MENSAL FUNSEG'!G8 -> 3019.1 | I14: ='CONSOLIDACAO MENSAL FUNSEG'!H8 -> 4191.53 | J14: ='CONSOLIDACAO MENSAL FUNSEG'!I8 -> 3960.94 | K14: ='CONSOLIDACAO MENSAL FUNSEG'!J8 -> 2760.17 | ... O14: ='CONSOLIDACAO MENSAL FUNSEG'!N8 -> 0
A15: Funseg | B15: Extra Judicial | C15: - OUTROS EMOLUMENTOS E CUSTAS EXTRA JUDICIAIS | D15: ='CONSOLIDACAO MENSAL FUNSEG'!C9 -> 0 | E15: ='CONSOLIDACAO MENSAL FUNSEG'!D9 -> 0 | F15: ='CONSOLIDACAO MENSAL FUNSEG'!E9 -> 0 | G15: ='CONSOLIDACAO MENSAL FUNSEG'!F9 -> 0 | H15: ='CONSOLIDACAO MENSAL FUNSEG'!G9 -> 0 | I15: ='CONSOLIDACAO MENSAL FUNSEG'!H9 -> 0 | J15: ='CONSOLIDACAO MENSAL FUNSEG'!I9 -> 0 | K15: ='CONSOLIDACAO MENSAL FUNSEG'!J9 -> 0 | ... O15: ='CONSOLIDACAO MENSAL FUNSEG'!N9 -> 0
